Workbook

Sheet 안내
A1: 마블 라이벌즈 영웅 데이터 정리 (한글판)
A2: 작성일 | B2: 2026년 10월 15일 (데이터 수집 시점 기준)
A3: 데이터 범위 | B3: 전체 영웅 54명 (위키 기준 시즌 10 시점: 뱅가드 14명 · 듀얼리스트 27명 · 전략가 12명 · 멀티 역할 1명(데드풀))
A4: 주 출처 | B4: 마블 라이벌즈 팬덤 위키 – 영웅 문서의 기본 정보(역할·체력·난이도)와 영웅별 스킬 표 (PC 키 기준)
A5: 보조 출처 | B5: 마블 라이벌즈 공식 홈페이지(한국어) 영웅 목록 – 한글 영웅명 확인용 (33명만 게재)
A7: 시트 구성
A8: 영웅 요약 | B8: 영웅 1명당 1줄: 역할, 체력, 난이도, 이동 속도, 일반 공격, 궁극기 이름·비용, 패시브, 협공 스킬, 스킬 개수
A9: 스킬 상세 | B9: 스킬 1개당 1줄 (601줄): 유형, 키, 쿨타임, 궁극기 비용, 세부 수치(피해량·사거리·지속 시간 등), 설명
A10: 협공 스킬 | B10: 협공(팀업) 스킬만 모아 영웅 ↔ 파트너 관계로 정리 (폼별 중복 제거)
A11: 출처 | B11: 사용한 페이지 주소 목록
A13: 용어 풀이
A14: 체력 'A+B 재생 보호막' | B14: 기본 체력 A에 더해, 한동안 피해를 받지 않으면 다시 차오르는 보호막 B를 가진다는 뜻 (예: 블랙 팬서 150+125)
A15: 보너스 체력 | B15: 잠깐 동안 체력 위에 덧씌워지는 추가 체력(파란 막대). 대부분 몇 초 뒤 줄어듭니다
A16: 궁극기 비용 | B16: 궁극기를 쓰기 위해 모아야 하는 에너지 양. 숫자가 작을수록 궁극기를 자주 쓸 수 있습니다
A17: 쿨타임 | B17: 스킬을 다시 쓸 수 있을 때까지 기다리는 시간. 충전식 스킬(여러 번 저장)은 쿨타임 칸이 비어 있고, '세부 수치'에 충전 횟수·충전 시간이 적혀 있습니다
A18: 난이도 | B18: 위키에 적힌 1~5 단계 값 (숫자가 클수록 어려움). 데드풀은 위키에 값이 없어 '위키 미기재'
A19: 폼/모드 | B19: 변신·모드가 있는 영웅의 상태 구분 (예: 헐크 – 브루스 배너/히어로 헐크/몬스터 헐크, 매직 – 다크차일드)
A21: 주의 사항 (확인되지 않은 부분)
A22: 번역 | B22: 스킬 이름·설명·수치 설명은 위키의 영어 원문을 번역한 것이며, 게임 안의 공식 한글 표기와 다를 수 있습니다. 위키에서 찾아볼 수 있도록 '스킬 상세' 맨 오른쪽에 원문 스킬명을 참고용으로 남겨 두었습니다
A23: 이동 속도 | B23: 영웅별 개별 수치를 찾지 못했습니다. 위키에 '대부분 6m/s, 블랙 팬서·울버린 등은 7m/s'라고만 적혀 있어 그대로 옮겼고, 나머지는 '6 (일반값, 개별 미확인)'으로 표기했습니다
A24: 한글 영웅명 | B24: 공식 한국어 영웅 목록에 없는 21명은 국내에서 흔히 쓰는 표기로 적고 '통상 표기'로 구분했습니다
A25: 수치 최신성 | B25: 위키는 이용자가 편집하는 자료라 최신 밸런스 패치가 늦게 반영될 수 있습니다. 위키에 '구버전 정보' 표시가 있는 항목(피닉스 일반 공격 설명)은 그대로 남겼습니다
A26: 제외 항목 | B26: 추천 콤보: 공식 수치가 아닌 커뮤니티 의견이라 제외했습니다 (카운터픽은 이후 요청에 따라 별도 시트로 추가)
A27: 자동 계산 | B27: '영웅 요약'의 스킬 수 열은 '스킬 상세' 시트를 세는 수식입니다 (데이터를 고치면 자동으로 다시 계산됨)
A29: 추가 데이터 (2026-10-15)
A30: 티어 목록 | B30: counterwatch.gg 티어 리스트: 커뮤니티 경기 승률로 S~F 분류
A31: 카운터 | B31: counterwatch.gg 카운터: 영웅별 가장 강한 카운터 5명과 역카운터 3명
A32: 조합 성향(PDR) | B32: counterwatch.gg 팀 빌더의 영웅별 P(포킹)·D(다이브)·R(러쉬) 점수
A33: 주의 | B33: 세 항목 모두 공식 데이터가 아닌 제3자 사이트의 커뮤니티 통계입니다. 매일 갱신되므로 수집일 기준 스냅샷으로 보세요. 이전 요청에서 제외했던 카운터픽은 이번 요청에 따라 출처를 밝혀 추가했습니다. 추천 콤보는 여전히 포함하지 않았습니다
A35: 맵 (2026-10-16 추가) | B35: 일반 모드 맵 18개를 경쟁(도미네이션) 6 · 호송(콘보이) 6 · 경쟁+호송(컨버전스) 6으로 나누고, 출시일과 맵별 승률 상위 영웅을 정리

Sheet 영웅 요약
A1: 번호 | B1: 영웅 | C1: 한글명 근거 | D1: 역할 | E1: 체력 | F1: 난이도(1~5) | G1: 이동 속도(m/s) | H1: 일반 공격 | I1: 일반 공격 피해량 | J1: 궁극기 | K1: 궁극기 비용 | L1: 패시브 | M1: 협공 스킬 (파트너) | N1: 폼/모드 | O1: 스킬 수 | P1: 위키 문서 | Q1: 티어(승률) | R1: 주 성향(PDR) | S1: P/D/R 점수 | T1: 가장 강한 카운터 TOP3 | U1: 이 영웅이 강한 상대
A2: 1 | B2: 아담 워록 | C2: 공식 한국어 영웅 목록 | D2: 전략가(힐러) | E2: 275 | F2: 3 | G2: 6 (일반값, 개별 미확인) | H2: 양자 마법 | I2: 양자 마법: 60 | J2: 업보의 부활 | K2: 4500 | L2: 재생의 고치 | M2: 우주 회오리 (스톰) / 완벽한 설계 (울트론) | N2: - | O2: =COUNTIF('스킬 상세'!$A:$A,B2) -> 9 | P2: 위키 문서 열기 | Q2: B (50.6%) | R2: P | S2: P 80% · D 20% · R 30% | T2: 블랙 팬서(+9.1), 스파이더맨(+6.8), 닥터 스트레인지(+6.5) | U2: 울트론, 스톰, 페니 파커
A3: 2 | B3: 앤젤라 | C3: 통상 표기(공식 미확인) | D3: 뱅가드(탱커) | E3: 350+200 재생 보호막 | F3: 4 | G3: 6 (일반값, 개별 미확인) | H3: 이코르의 창 / 이코르의 도끼 | I3: 이코르의 창: 45 / 이코르의 도끼: 첫 세 번의 일격: 30, 네 번째 일격: 50 | J3: 헤븐의 응징 | K3: 3100 | L3: 세라핌의 비상 | M3: 오딘이 인정하지 않은 자들 (로키) / 애즈가디언즈 오브 갤럭시 (스타 로드) | N3: - | O3: =COUNTIF('스킬 상세'!$A:$A,B3) -> 10 | P3: 위키 문서 열기 | Q3: A (51.9%) | R3: R | S3: P 0% · D 90% · R 100% | T3: 데빌 다이노서(+21.9), 씽(+12.9), 토르(+9.2) | U3: 블랙 팬서, 스파이더맨, 로켓 라쿤
A4: 3 | B4: 블랙 캣 | C4: 통상 표기(공식 미확인) | D4: 듀얼리스트(딜러) | E4: 150+125 재생 보호막 | F4: 4 | G4: 6 (일반값, 개별 미확인) | H4: 고양이의 분노 / 발톱 채찍 | I4: 고양이의 분노: 35 / 발톱 채찍: 65 | J4: 명함 | K4: 3100 | L4: 은밀한 캣워크 / 말킨의 불운 / 끈적한 발바닥 | M4: 고양이 동맹 (블랙 팬서) / 결속의 끈 (스파이더맨) | N4: 기본 / 길디드 딜(특수 상점) | O4: =COUNTIF('스킬 상세'!$A:$A,B4) -> 21 | P4: 위키 문서 열기 | Q4: C (50.0%) | R4: D | S4: P 10% · D 100% · R 70% | T4: 씽(+12.8), 데빌 다이노서(+12.3), 페니 파커(+11.7) | U4: 로켓 라쿤, 맨티스, 인비저블 우먼
A5: 4 | B5: 블랙 팬서 | C5: 공식 한국어 영웅 목록 | D5: 듀얼리스트(딜러) | E5: 150+125 재생 보호막 | F5: 4 | G5: 7 | H5: 비브라늄 발톱 | I5: 비브라늄 발톱: 35 | J5: 바스트의 강림 | K5: 3300 | L5: 팬서의 교활함 | M5: 다미사-야오 (스톰) / 차원 지름길 (매직) | N5: - | O5: =COUNTIF('스킬 상세'!$A:$A,B5) -> 9 | P5: 위키 문서 열기 | Q5: B (50.6%) | R5: D | S5: P 10% · D 90% · R 70% | T5: 씽(+17.7), 앤젤라(+15.5), 페니 파커(+15.4) | U5: 땅상어 제프, 로켓 라쿤, 인비저블 우먼
A6: 5 | B6: 블랙 위도우 | C6: 공식 한국어 영웅 목록 | D6: 듀얼리스트(딜러) | E6: 250 | F6: 4 | G6: 6 (일반값, 개별 미확인) | H6: 위도우스 바이트 진압봉 / 레드 룸 소총 | I6: 위도우스 바이트 진압봉: 45 / 레드 룸 소총: 발당 45 | J6: 암살자의 집중 | K6: 3100 | L6: - | M6: 연합 요원 (호크아이) / 불타는 탄환 (피닉스) | N6: - | O6: =COUNTIF('스킬 상세'!$A:$A,B6) -> 9 | P6: 위키 문서 열기 | Q6: D (47.6%) | R6: P | S6: P 80% · D 60% · R 30% | T6: 인비저블 우먼(+11.2), 클록 앤 대거(+10.5), 캡틴 아메리카(+9.9) | U6: 울트론, 아이언맨, 스톰
A7: 6 | B7: 블레이드 | C7: 통상 표기(공식 미확인) | D7: 듀얼리스트(딜러) | E7: 350 | F7: 3 | G7: 6 (일반값, 개별 미확인) | H7: 선조의 검 / 사냥꾼의 산탄총 | I7: 선조의 검: 단일 베기: 26, 이중 타격: 타격당 13 / 사냥꾼의 산탄총: 발당 45 | J7: 천 겹 베기 | K7: 2800 | L7: - | M7: 콘슈의 칼날 (문나이트) / 전투를 위한 피 (캡틴 아메리카) | N7: - | O7: =COUNTIF('스킬 상세'!$A:$A,B7) -> 8 | P7: 위키 문서 열기 | Q7: A (52.0%) | R7: D | S7: P 10% · D 100% · R 90% | T7: 휴먼 토치(+8.3), 울트론(+7.3), 페니 파커(+7.3) | U7: 닥터 스트레인지, 클록 앤 대거, 로켓 라쿤
A8: 7 | B8: 캡틴 아메리카 | C8: 공식 한국어 영웅 목록 | D8: 뱅가드(탱커) | E8: 350+300 재생 보호막 | F8: 3 | G8: 6 (일반값, 개별 미확인) | H8: 센티넬 일격 | I8: 센티넬 일격: 근접: 45, 방패 던지기: 45 | J8: 자유의 돌격 | K8: 3100 | L8: - | M8: 전압 결합 (토르) / 별의 정렬 (윈터 솔져) | N8: - | O8: =COUNTIF('스킬 상세'!$A:$A,B8) -> 9 | P8: 위키 문서 열기 | Q8: A (51.8%) | R8: D/R | S8: P 20% · D 90% · R 90% | T8: 데빌 다이노서(+17.8), 울버린(+10.0), 페니 파커(+9.8) | U8: 로켓 라쿤, 인비저블 우먼, 블랙 위도우
A9: 8 | B9: 클록 앤 대거 | C9: 공식 한국어 영웅 목록 | D9: 전략가(힐러) | E9: 275 | F9: 3 | G9: 6 (일반값, 개별 미확인) | H9: 라이트포스 단검 / 다크포스 망토 | I9: 라이트포스 단검: 발당 18 / 다크포스 망토: 80/s | J9: 영원한 결속 | K9: 4500 | L9: - | M9: 망각의 장막 (후드) / 얼어붙은 안식처 (루나 스노우) | N9: 대거 / 클록 | O9: =COUNTIF('스킬 상세'!$A:$A,B9) -> 14 | P9: 위키 문서 열기 | Q9: D (48.3%) | R9: D/R | S9: P 30% · D 80% · R 80% | T9: 블랙 팬서(+9.4), 매직(+7.6), 블레이드(+7.0) | U9: 피닉스, 블랙 위도우, 퍼니셔
A10: 9 | B10: 사이클롭스 | C10: 통상 표기(공식 미확인) | D10: 듀얼리스트(딜러) | E10: 275 | F10: 2 | G10: 6 (일반값, 개별 미확인) | H10: 광학 블래스트 / 충격 광선 | I10: 광학 블래스트: 틱당 23 / 충격 광선: 틱당 11.5 | J10: 루비 분노 | K10: 3400 | L10: 키네틱 호버 | M10: 날씬하고 빨간 (피닉스) / 키네틱 혈족 (갬빗) | N10: - | O10: =COUNTIF('스킬 상세'!$A:$A,B10) -> 9 | P10: 위키 문서 열기 | Q10: F (45.8%) | R10: P | S10: P 90% · D 20% · R 50% | T10: 로켓 라쿤(+8.0), 클록 앤 대거(+6.3), 주빌리(+5.0) | U10: 데빌 다이노서, 울버린, 아이언맨
A11: 10 | B11: 데어데블 | C11: 통상 표기(공식 미확인) | D11: 듀얼리스트(딜러) | E11: 150+150 재생 보호막 | F11: 3 | G11: 6 (일반값, 개별 미확인) | H11: 정의의 잽 / 정의의 십자가 | I11: 정의의 잽: 35 / 정의의 십자가: 50 | J11: 악마 해방 | K11: 3400 | L11: 레이더 감각 / 맹목적 상승 | M11: 종합 방어 (아이언피스트) / 악마 같은 거래 (블랙 위도우) | N11: - | O11: =COUNTIF('스킬 상세'!$A:$A,B11) -> 11 | P11: 위키 문서 열기 | Q11: B (51.3%) | R11: D | S11: P 10% · D 100% · R 90% | T11: 데빌 다이노서(+15.3), 페니 파커(+14.6), 로그(+10.4) | U11: 로켓 라쿤, 인비저블 우먼, 사일록
A12: 11 | B12: 데드풀 | C12: 통상 표기(공식 미확인) | D12: 뱅가드(탱커) / 듀얼리스트(딜러) / 전략가(힐러) | E12: 500 / 275 / 275 | F12: 위키 미기재 | G12: 6 (일반값, 개별 미확인) | H12: 쌍 데저트 이글 - 뱅가드 / 끝내주는 카타나 - 뱅가드 / 쌍 데저트 이글 - 뱅가드 강화 / 끝내주는 카타나 - 뱅가드 강화 / 쌍 데저트 이글 - 듀얼리스트 / 끝내주는 카타나 - 듀얼리스트 / 쌍 데저트 이글 - 듀얼리스트 강화 / 끝내주는 카타나 - 듀얼리스트 강화 / 쌍 데저트 이글 - 전략가 / 끝내주는 카타나 - 전략가 / 쌍 데저트 이글 - 전략가 강화 / 끝내주는 카타나 - 전략가 강화 | I12: 쌍 데저트 이글 - 뱅가드: 발당 36 / 끝내주는 카타나 - 뱅가드: 30 / 쌍 데저트 이글 - 뱅가드 강화: 발당 40 / 끝내주는 카타나 - 뱅가드 강화: 35 / 쌍 데저트 이글 - 듀얼리스트: 발당 42 / 끝내주는 카타나 - 듀얼리스트: 40 / 쌍 데저트 이글 - 듀얼리스트 강화: 발당 46 / 끝내주는 카타나 - 듀얼리스트 강화: 45 / 쌍 데저트 이글 - 전략가: 발당 25 / 끝내주는 카타나 - 전략가: 30 / 쌍 데저트 이글 - 전략가 강화: 발당 28 / 끝내주는 카타나 - 전략가 강화: 35 | J12: 밴 해머 / 대시험 / 밴 해머 - 강화 / 대시험 - 강화 / 실력 문제 / 깜짝 퀴즈! / 실력 문제 - 강화 / 깜짝 퀴즈! - 강화 / 완벽 압살 / 기말고사 / 완벽 압살 - 강화 / 기말고사 - 강화 | K12: 에너지 대신 스타일 S랭크 달성 시 사용 (쿨타임 60초) | L12: 힐링 팩터 / 최고의 감각 | M12: "헬-예, 허니" (헬라) / 검보 치미창가 (갬빗) | N12: 뱅가드 / 데저트 이글(총) / 뱅가드 / 카타나(검) / 뱅가드 / 스킬 강화 / 듀얼리스트 / 데저트 이글(총) / 듀얼리스트 / 카타나(검) / 듀얼리스트 / 스킬 강화 / 전략가 / 데저트 이글(총) / 전략가 / 카타나(검) / 전략가 / 스킬 강화 | O12: =COUNTIF('스킬 상세'!$A:$A,B12) -> 87 | P12: 위키 문서 열기 | Q12: [전략가] D (47.7%) / [듀얼리스트] D (47.4%) / [뱅가드] F (46.3%) | R12: [전략가] R / [듀얼리스트] D / [뱅가드] R | S12: [전략가] P 60% · D 50% · R 90% / [듀얼리스트] P 50% · D 100% · R 80% / [뱅가드] P 40% · D 70% · R 100% | T12: [전략가] 블레이드(+5.3), 문나이트(+5.2), 클록 앤 대거(+5.0) / [듀얼리스트] 씽(+5.3), 베놈(+4.8), 고르(+4.4) / [뱅가드] 주빌리(+7.5), 클록 앤 대거(+5.3), 화이트 폭스(+5.1) | U12: [전략가] 울버린, 고르, 아이언피스트 / [듀얼리스트] 아이언맨, 인비저블 우먼, 맨티스 / [뱅가드] 아이언맨, 휴먼 토치, 울트론
A13: 12 | B13: 데빌 다이노서 | C13: 통상 표기(공식 미확인) | D13: 뱅가드(탱커) | E13: 825 | F13: 3 | G13: 6 (일반값, 개별 미확인) | H13: 원시의 물어뜯기 | I13: 원시의 물어뜯기: 75 | J13: 악마 야수의 광란 | K13: 3400 | L13: 선사 시대 장갑 / 최상위 우위 | M13: 원시의 응징 (퍼니셔) / 바다와 육지 (땅상어 제프) | N13: - | O13: =COUNTIF('스킬 상세'!$A:$A,B13) -> 10 | P13: 위키 문서 열기 | Q13: A (52.7%) | R13: R | S13: P 10% · D 30% · R 100% | T13: 스쿼럴 걸(+14.8), 피닉스(+14.6), 퍼니셔(+14.3) | U13: 앤젤라, 캡틴 아메리카, 미스터 판타스틱
A14: 13 | B14: 닥터 스트레인지 | C14: 공식 한국어 영웅 목록 | D14: 뱅가드(탱커) | E14: 650 | F14: 2 | G14: 6 (일반값, 개별 미확인) | H14: 데낙의 단검 | I14: 데낙의 단검: 타격당 18 | J14: 아가모토의 눈 | K14: 3100 | L14: 마법의 대가 | M14: 감마 소용돌이 (헐크(브루스 배너)) / 사이오닉 소용돌이 (인비저블 우먼) | N14: - | O14: =COUNTIF('스킬 상세'!$A:$A,B14) -> 9 | P14: 위키 문서 열기 | Q14: B (50.3%) | R14: P | S14: P 80% · D 70% · R 30% | T14: 울버린(+19.1), 데빌 다이노서(+13.5), 씽(+12.1) | U14: 스파이더맨, 아담 워록, 블랙 위도우
A15: 14 | B15: 엘사 블러드스톤 | C15: 통상 표기(공식 미확인) | D15: 듀얼리스트(딜러) | E15: 250 | F15: 3 | G15: 6 (일반값, 개별 미확인) | H15: 더블 배럴 블래스터 / 괴물 관통자 | I15: 더블 배럴 블래스터: 펠릿당 4.5 / 괴물 관통자: 12 + 최대 체력의 0.8% | J15: 최상위 포식자 | K15: 3400 | L15: 물려받은 본능 | M15: 선사 시대 덫 (데빌 다이노서) / 수다쟁이 용병들 (데드풀) | N15: - | O15: =COUNTIF('스킬 상세'!$A:$A,B15) -> 10 | P15: 위키 문서 열기 | Q15: D (47.7%) | R15: P | S15: P 80% · D 40% · R 60% | T15: 클록 앤 대거(+9.0), 인비저블 우먼(+8.2), 땅상어 제프(+8.1) | U15: 울버린, 데빌 다이노서, 씽
A16: 15 | B16: 엠마 프로스트 | C16: 통상 표기(공식 미확인) | D16: 뱅가드(탱커) | E16: 675 | F16: 3 | G16: 6 (일반값, 개별 미확인) | H16: 텔레파시 파동 / 다면체의 분노 | I16: 텔레파시 파동: 게이지에 따라 피해 증가: / • 게이지 0 - 70/s / • 게이지 99 - 110/s / • 게이지 100 - 140/s / 다면체의 분노: 1·2번째 타격: 50, 3번째 타격: 70, 4번째 타격: 80 | J16: 사이오닉 유혹 | K16: 3100 | L16: - | M16: 영혼 파괴자 (맨티스) / 아이스드 아웃 다이아몬드 (루나 스노우) | N16: 사이오닉(기본) / 다이아몬드 폼 | O16: =COUNTIF('스킬 상세'!$A:$A,B16) -> 12 | P16: 위키 문서 열기 | Q16: C (48.9%) | R16: R | S16: P 70% · D 50% · R 90% | T16: 울버린(+9.8), 로켓 라쿤(+7.1), 인비저블 우먼(+5.2) | U16: 매그니토, 미스터 판타스틱, 스파이더맨
A17: 16 | B17: 갬빗 | C17: 통상 표기(공식 미확인) | D17: 전략가(힐러) | E17: 250 | F17: 4 | G17: 6 (일반값, 개별 미확인) | H17: 키네틱 카드 | I17: 키네틱 카드: 카드당 20 | J17: 분노의 로열 플러시 | K17: 4500 | L17: - | M17: 유리한 확률 (매그니토) / 반짝이는 지팡이 (주빌리) | N17: - | O17: =COUNTIF('스킬 상세'!$A:$A,B17) -> 12 | P17: 위키 문서 열기 | Q17: C (49.0%) | R17: P/D | S17: P 90% · D 90% · R 50% | T17: 블랙 팬서(+10.7), 스파이더맨(+7.0), 베놈(+5.2) | U17: 퍼니셔, 데빌 다이노서, 헬라
A18: 17 | B18: 고르 | C18: 통상 표기(공식 미확인) | D18: 듀얼리스트(딜러) | E18: 175+175 재생 보호막 | F18: 4 | G18: 6 (일반값, 개별 미확인) | H18: 올 블랙 | I18: 올 블랙: 1/3타: 20, 2/4타: 30 | J18: 신들의 황혼 | K18: 3400 | L18: 심비오트 떼 | M18: 라그나로크 (헬라) / 군체 의식 (베놈) | N18: - | O18: =COUNTIF('스킬 상세'!$A:$A,B18) -> 9 | P18: 위키 문서 열기 | Q18: S (54.8%) | R18: D | S18: P 20% · D 90% · R 80% | T18: 페니 파커(+12.8), 데빌 다이노서(+11.4), 울트론(+10.4) | U18: 블랙 캣, 스파이더맨, 맨티스
A19: 18 | B19: 그루트 | C19: 공식 한국어 영웅 목록 | D19: 뱅가드(탱커) | E19: 850 | F19: 2 | G19: 6 (일반값, 개별 미확인) | H19: 덩굴 일격 | I19: 덩굴 일격: 65 | J19: 교살의 감옥 | K19: 2800 | L19: 플로라 콜로서스 | M19: 야생의 벽 (맨티스) / 버블 친구들 (땅상어 제프) | N19: - | O19: =COUNTIF('스킬 상세'!$A:$A,B19) -> 9 | P19: 위키 문서 열기 | Q19: C (49.4%) | R19: R | S19: P 50% · D 20% · R 90% | T19: 울버린(+14.7), 데빌 다이노서(+10.6), 주빌리(+6.6) | U19: 미스터 판타스틱, 블랙 팬서, 데어데블
A20: 19 | B20: 호크아이 | C20: 공식 한국어 영웅 목록 | D20: 듀얼리스트(딜러) | E20: 250 | F20: 4 | G20: 6 (일반값, 개별 미확인) | H20: 관통 화살 / 폭발 화살 | I20: 관통 화살: 28 - 70 (0.9s 당기면 최대 피해) / 폭발 화살: 투사체: 발당 16, 폭발: 발당 34 | J20: 사냥꾼의 시야 | K20: 3100 | L20: 궁수의 집중 | M20: 센본자쿠라 일격 (사일록) / 달빛 베기 (클록 앤 대거) | N20: - | O20: =COUNTIF('스킬 상세'!$A:$A,B20) -> 10 | P20: 위키 문서 열기 | Q20: D (48.0%) | R20: P | S20: P 90% · D 30% · R 10% | T20: 블랙 팬서(+12.1), 인비저블 우먼(+9.2), 블랙 캣(+8.9) | U20: 페니 파커, 데빌 다이노서, 씽
A21: 20 | B21: 헬라 | C21: 공식 한국어 영웅 목록 | D21: 듀얼리스트(딜러) | E21: 250 | F21: 3 | G21: 6 (일반값, 개별 미확인) | H21: 밤칼 가시 | I21: 밤칼 가시: 발당 80 | J21: 죽음의 여신 | K21: 4000 | L21: 나스트론드 까마귀 폭풍 | M21: 헬의 촉수 (베놈) / 심해의 분노 (네이머) | N21: - | O21: =COUNTIF('스킬 상세'!$A:$A,B21) -> 9 | P21: 위키 문서 열기 | Q21: A (51.6%) | R21: P/D | S21: P 80% · D 80% · R 50% | T21: 인비저블 우먼(+12.0), 블랙 팬서(+11.2), 클록 앤 대거(+8.6) | U21: 스칼렛 위치, 데빌 다이노서, 울트론
A22: 21 | B22: 헐크 | C22: 공식 한국어 영웅 목록 | D22: 뱅가드(탱커) | E22: 200 (브루스 배너) / 400+300 재생 보호막 (히어로 헐크) / 1500 (몬스터 헐크) | F22: 4 | G22: 6 (일반값, 개별 미확인) | H22: 감마선 총 / 묵직한 일격 | I22: 감마선 총: 발당 16 / 묵직한 일격: 45 / 묵직한 일격: 70 | J22: 약골 배너 / 헐크 스매시! / 세계 파괴자 | K22: 약골 배너: 600 / 헐크 스매시!: 3,700 | L22: - | M22: 야만의 강타 (캡틴 아메리카) / 감마 강속구 (울버린) | N22: 브루스 배너 / 히어로 헐크 / 몬스터 헐크 | O22: =COUNTIF('스킬 상세'!$A:$A,B22) -> 16 | P22: 위키 문서 열기 | Q22: A (52.2%) | R22: R | S22: P 10% · D 80% · R 90% | T22: 데빌 다이노서(+12.0), 페니 파커(+10.0), 후드(+8.7) | U22: 블랙 팬서, 클록 앤 대거, 로키
A23: 22 | B23: 휴먼 토치 | C23: 통상 표기(공식 미확인) | D23: 듀얼리스트(딜러) | E23: 250 | F23: 3 | G23: 6 (일반값, 개별 미확인) | H23: 화염 뭉치 | I23: 화염 뭉치: 산탄당 5.5 | J23: 초신성 | K23: 3400 | L23: - | M23: 불꽃 스파크 (주빌리) / 폭풍의 점화 (스톰) | N23: - | O23: =COUNTIF('스킬 상세'!$A:$A,B23) -> 8 | P23: 위키 문서 열기 | Q23: B (50.3%) | R23: D | S23: P 80% · D 90% · R 20% | T23: 스파이더맨(+11.8), 앤젤라(+8.2), 데드풀(뱅가드)(+6.7) | U23: 스쿼럴 걸, 울버린, 문나이트
A24: 23 | B24: 인비저블 우먼 | C24: 통상 표기(공식 미확인) | D24: 전략가(힐러) | E24: 275 | F24: 4 | G24: 6 (일반값, 개별 미확인) | H24: 구체 투사 | I24: 구체 투사: 발사: 30, 귀환: 15 | J24: 투명 경계 | K24: 4300 | L24: 은밀한 전진 | M24: 단결한 남매 (휴먼 토치) / 퍼스트 패밀리 (미스터 판타스틱) | N24: - | O24: =COUNTIF('스킬 상세'!$A:$A,B24) -> 10 | P24: 위키 문서 열기 | Q24: D (48.4%) | R24: P | S24: P 60% · D 30% · R 40% | T24: 데어데블(+17.5), 블랙 팬서(+14.3), 스파이더맨(+11.2) | U24: 퍼니셔, 헬라, 블랙 위도우
A25: 24 | B25: 아이언피스트 | C25: 공식 한국어 영웅 목록 | D25: 듀얼리스트(딜러) | E25: 300 | F25: 4 | G25: 6 (일반값, 개별 미확인) | H25: 절권도 / 일지충권 | I25: 절권도: 1/2/5타: 38 / 3/4타: 15 / 6타: 60 / 일지충권: 8 + 최대 체력의 3.1% | J25: 살아있는 기 | K25: 3100 | L25: 기 흡수 | M25: 강철과 바위 (씽) / 구미호 장 (화이트 폭스) | N25: - | O25: =COUNTIF('스킬 상세'!$A:$A,B25) -> 11 | P25: 위키 문서 열기 | Q25: B (51.1%) | R25: R | S25: P 0% · D 80% · R 90% | T25: 페니 파커(+7.2), 스칼렛 위치(+7.0), 화이트 폭스(+6.1) | U25: 로켓 라쿤, 닥터 스트레인지, 후드
A26: 25 | B26: 아이언맨 | C26: 공식 한국어 영웅 목록 | D26: 듀얼리스트(딜러) | E26: 250 | F26: 2 | G26: 6 (일반값, 개별 미확인) | H26: 리펄서 블래스트 / 유니빔 | I26: 리펄서 블래스트: 투사체: 35, 효과 범위: 45 / 유니빔: 140/s | J26: 무적 펄스 캐논 | K26: 3400 | L26: - | M26: 감마 돌진 (헐크(브루스 배너)) / 천둥 오버드라이브 (토르) | N26: - | O26: =COUNTIF('스킬 상세'!$A:$A,B26) -> 8 | P26: 위키 문서 열기 | Q26: A (51.6%) | R26: P | S26: P 90% · D 50% · R 20% | T26: 스파이더맨(+16.2), 블랙 위도우(+11.5), 로켓 라쿤(+8.5) | U26: 스쿼럴 걸, 울버린, 페니 파커
A27: 26 | B27: 땅상어 제프 | C27: 공식 한국어 영웅 목록 | D27: 전략가(힐러) | E27: 250 | F27: 1 | G27: 6 (일반값, 개별 미확인) | H27: 즐거운 물장구 | I27: 즐거운 물장구: 70/s | J27: 제프다! | K27: 4500 | L27: 천진난만한 귀여움 | M27: 심해의 수호자 (베놈) / 미스터 풀의 차원 간 장난감 상자 (데드풀) | N27: - | O27: =COUNTIF('스킬 상세'!$A:$A,B27) -> 8 | P27: 위키 문서 열기 | Q27: F (46.9%) | R27: P | S27: P 60% · D 40% · R 50% | T27: 블랙 팬서(+22.3), 스파이더맨(+11.7), 블랙 캣(+9.5) | U27: 엘사 블러드스톤, 윈터 솔져, 울버린
A28: 27 | B28: 주빌리 | C28: 통상 표기(공식 미확인) | D28: 전략가(힐러) | E28: 275 | F28: 4 | G28: 6 (일반값, 개별 미확인) | H28: 에너지 플라즈모이드 | I28: 에너지 플라즈모이드: 발당 11 | J28: 불꽃놀이 피날레 | K28: 4300 | L28: 반짝 표식 | M28: 지옥불 스파크 (후드) / 흡혈귀 혈족 (블레이드) | N28: - | O28: =COUNTIF('스킬 상세'!$A:$A,B28) -> 8 | P28: 위키 문서 열기 | Q28: B (50.3%) | R28: P/D | S28: P 80% · D 80% · R 40% | T28: 블랙 팬서(+10.3), 스파이더맨(+7.7), 문나이트(+6.9) | U28: 페니 파커, 피닉스, 데빌 다이노서
A29: 28 | B29: 로키 | C29: 공식 한국어 영웅 목록 | D29: 전략가(힐러) | E29: 275 | F29: 4 | G29: 6 (일반값, 개별 미확인) | H29: 신비한 미사일 | I29: 신비한 미사일: 25 | J29: 장난의 신 | K29: 4500 | L29: - | M29: 악당의 환영 (헬라) / 활기찬 생명력 (맨티스) | N29: - | O29: =COUNTIF('스킬 상세'!$A:$A,B29) -> 9 | P29: 위키 문서 열기 | Q29: B (50.9%) | R29: P | S29: P 70% · D 60% · R 40% | T29: 스파이더맨(+10.8), 블랙 팬서(+8.7), 블랙 캣(+8.6) | U29: 네이머, 윈터 솔져, 퍼니셔
A30: 29 | B30: 루나 스노우 | C30: 공식 한국어 영웅 목록 | D30: 전략가(힐러) | E30: 275 | F30: 2 | G30: 6 (일반값, 개별 미확인) | H30: 빛과 어둠의 얼음 | I30: 빛과 어둠의 얼음: 발당 24 (총 최대 72) | J30: 두 세계의 운명 | K30: 4800 | L30: 극저온 심장 / 부드러운 스케이트 | M30: 아틀라스 결속 (화이트 폭스) / 이중성의 춤 (아담 워록) | N30: - | O30: =COUNTIF('스킬 상세'!$A:$A,B30) -> 10 | P30: 위키 문서 열기 | Q30: D (47.5%) | R30: P/D | S30: P 80% · D 80% · R 50% | T30: 블랙 팬서(+11.6), 캡틴 아메리카(+5.6), 데어데블(+5.5) | U30: 페니 파커, 퍼니셔, 데빌 다이노서
A31: 30 | B31: 매직 | C31: 공식 한국어 영웅 목록 | D31: 듀얼리스트(딜러) | E31: 150+125 재생 보호막 | F31: 3 | G31: 6 (일반값, 개별 미확인) | H31: 소울소드 | I31: 소울소드: 75 / 소울소드: 적중 시 0.15s마다 3회 피해, 회당 35 피해 | J31: 다크차일드 | K31: 3400 | L31: 림보의 힘 | M31: 사이토락의 사슬 (닥터 스트레인지) / 공허의 오망성 (후드) | N31: 매직(기본) / 다크차일드 | O31: =COUNTIF('스킬 상세'!$A:$A,B31) -> 19 | P31: 위키 문서 열기 | Q31: S (55.2%) | R31: D | S31: P 0% · D 90% · R 70% | T31: 페니 파커(+12.5), 씽(+12.0), 로그(+7.9) | U31: 맨티스, 인비저블 우먼, 로켓 라쿤
A32: 31 | B32: 매그니토 | C32: 공식 한국어 영웅 목록 | D32: 뱅가드(탱커) | E32: 600 | F32: 2 | G32: 6 (일반값, 개별 미확인) | H32: 강철 일제 사격 | I32: 강철 일제 사격: 투사체: 40, 효과 범위: 40 | J32: 메테오 M | K32: 3400 | L32: - | M32: 금속의 혼돈 (스칼렛 위치) / 자기 공명 (엠마 프로스트) | N32: - | O32: =COUNTIF('스킬 상세'!$A:$A,B32) -> 9 | P32: 위키 문서 열기 | Q32: C (49.5%) | R32: P | S32: P 80% · D 50% · R 60% | T32: 울버린(+18.0), 엠마 프로스트(+8.8), 씽(+7.9) | U32: 블랙 팬서, 헬라, 네이머
A33: 32 | B33: 맨티스 | C33: 공식 한국어 영웅 목록 | D33: 전략가(힐러) | E33: 250 | F33: 1 | G33: 6 (일반값, 개별 미확인) | H33: 생명 에너지 폭발 | I33: 생명 에너지 폭발: 발당 55 | J33: 영혼 부활 | K33: 4300 | L33: 자연의 은총 | M33: 별꽃 (스타 로드) / 생명의 계약 (아담 워록) | N33: - | O33: =COUNTIF('스킬 상세'!$A:$A,B33) -> 9 | P33: 위키 문서 열기 | Q33: S (56.1%) | R33: R | S33: P 70% · D 50% · R 80% | T33: 블랙 팬서(+13.2), 블랙 캣(+11.4), 매직(+9.5) | U33: 페니 파커, 데빌 다이노서, 호크아이
A34: 33 | B34: 미스터 판타스틱 | C34: 통상 표기(공식 미확인) | D34: 듀얼리스트(딜러) | E34: 375 | F34: 3 | G34: 6 (일반값, 개별 미확인) | H34: 늘어나는 펀치 | I34: 늘어나는 펀치: 70 | J34: 천재의 반동 | K34: 3100 | L34: 신축성 괴력 | M34: 판타스틱 증폭기 (로켓 라쿤) / 박살 연구부 (씽) | N34: - | O34: =COUNTIF('스킬 상세'!$A:$A,B34) -> 8 | P34: 위키 문서 열기 | Q34: S (53.1%) | R34: R | S34: P 50% · D 50% · R 80% | T34: 데빌 다이노서(+16.8), 씽(+12.8), 페니 파커(+12.4) | U34: 블랙 팬서, 스파이더맨, 블랙 캣
A35: 34 | B35: 문나이트 | C35: 공식 한국어 영웅 목록 | D35: 듀얼리스트(딜러) | E35: 275 | F35: 3 | G35: 6 (일반값, 개별 미확인) | H35: 초승달 다트 | I35: 초승달 다트: 발당 25 | J35: 콘슈의 손 | K35: 3100 | L35: - | M35: 빛나는 달 (클록 앤 대거) / 블러드 문 (엘사 블러드스톤) | N35: - | O35: =COUNTIF('스킬 상세'!$A:$A,B35) -> 10 | P35: 위키 문서 열기 | Q35: D (47.6%) | R35: P/D | S35: P 80% · D 80% · R 50% | T35: 울트론(+13.3), 블랙 팬서(+11.2), 스파이더맨(+10.6) | U35: 데빌 다이노서, 울버린, 씽
A36: 35 | B36: 네이머 | C36: 공식 한국어 영웅 목록 | D36: 듀얼리스트(딜러) | E36: 275 | F36: 2 | G36: 6 (일반값, 개별 미확인) | H36: 넵튠의 삼지창 | I36: 넵튠의 삼지창: 발당 80 | J36: 프로테우스의 뿔 | K36: 3100 | L36: - | M36: 감마 몬스트로 (헐크(브루스 배너)) / 서늘한 매력 (루나 스노우) | N36: - | O36: =COUNTIF('스킬 상세'!$A:$A,B36) -> 8 | P36: 위키 문서 열기 | Q36: D (47.2%) | R36: P | S36: P 80% · D 60% · R 40% | T36: 로켓 라쿤(+11.4), 인비저블 우먼(+7.3), 매그니토(+7.3) | U36: 스파이더맨, 스칼렛 위치, 아이언피스트
A37: 36 | B37: 페니 파커 | C37: 공식 한국어 영웅 목록 | D37: 뱅가드(탱커) | E37: 650 | F37: 4 | G37: 6 (일반값, 개별 미확인) | H37: 사이버 거미줄 뭉치 | I37: 사이버 거미줄 뭉치: 투사체: 15, 효과 범위: 15 | J37: 스파이더 스위퍼 | K37: 3400 | L37: - | M37: 비브라늄 메카 (블랙 팬서) / 로켓 네트워크 (로켓 라쿤) | N37: - | O37: =COUNTIF('스킬 상세'!$A:$A,B37) -> 9 | P37: 위키 문서 열기 | Q37: S (57.7%) | R37: P | S37: P 70% · D 40% · R 60% | T37: 로켓 라쿤(+13.7), 퍼니셔(+12.7), 주빌리(+11.8) | U37: 블랙 팬서, 데어데블, 고르
A38: 37 | B38: 피닉스 | C38: 통상 표기(공식 미확인) | D38: 듀얼리스트(딜러) | E38: 250 | F38: 3 | G38: 6 (일반값, 개별 미확인) | H38: 우주의 불꽃 | I38: 우주의 불꽃: 발당 65 | J38: 엔드송 인페르노 | K38: 3100 | L38: - | M38: 생명의 순환 (헬라) / 염동력 난타 (로그) | N38: - | O38: =COUNTIF('스킬 상세'!$A:$A,B38) -> 7 | P38: 위키 문서 열기 | Q38: F (45.6%) | R38: P | S38: P 90% · D 80% · R 70% | T38: 클록 앤 대거(+10.9), 주빌리(+9.9), 인비저블 우먼(+9.8) | U38: 데빌 다이노서, 페니 파커, 울버린
A39: 38 | B39: 사일록 | C39: 공식 한국어 영웅 목록 | D39: 듀얼리스트(딜러) | E39: 100+150 재생 보호막 | F39: 5 | G39: 6 (일반값, 개별 미확인) | H39: 사이오닉 석궁 | I39: 사이오닉 석궁: 탄환당 12 | J39: 나비의 춤 | K39: 3400 | L39: - | M39: 정신 투사 (엠마 프로스트) / 빛과 어둠의 다트 (클록 앤 대거) | N39: - | O39: =COUNTIF('스킬 상세'!$A:$A,B39) -> 7 | P39: 위키 문서 열기 | Q39: B (50.6%) | R39: D | S39: P 50% · D 90% · R 60% | T39: 데어데블(+9.3), 블랙 팬서(+9.0), 블랙 캣(+7.0) | U39: 울트론, 울버린, 스톰
A40: 39 | B40: 로켓 라쿤 | C40: 공식 한국어 영웅 목록 | D40: 전략가(힐러) | E40: 250 | F40: 1 | G40: 6 (일반값, 개별 미확인) | H40: 포격 모드 / 수리 모드 | I40: 포격 모드: 발당 17 / 수리 모드: - | J40: C.Y.A. (몸 사려) | K40: 4300 | L40: - | M40: 포유류의 결속 (스쿼럴 걸) / 행성 X 친구들 (그루트) | N40: - | O40: =COUNTIF('스킬 상세'!$A:$A,B40) -> 9 | P40: 위키 문서 열기 | Q40: S (53.7%) | R40: P | S40: P 80% · D 50% · R 40% | T40: 블랙 팬서(+19.6), 데어데블(+18.4), 블랙 캣(+17.4) | U40: 페니 파커, 스쿼럴 걸, 네이머
...

Sheet 티어 목록
A1: 티어 | B1: 순위 | C1: 영웅 | D1: 승률(%) | E1: 주 성향 | F1: 티어 기준
A2: S | B2: 1 | C2: 페니 파커 | D2: 57.7 | E2: P | F2: 승률 53% 이상
A3: S | B3: 2 | C3: 울트론 | D3: 57 | E3: P | F3: 승률 53% 이상
A4: S | B4: 3 | C4: 스톰 | D4: 56.5 | E4: P/D | F4: 승률 53% 이상
A5: S | B5: 4 | C5: 맨티스 | D5: 56.1 | E5: R | F5: 승률 53% 이상
A6: S | B6: 5 | C6: 매직 | D6: 55.2 | E6: D | F6: 승률 53% 이상
A7: S | B7: 6 | C7: 고르 | D7: 54.8 | E7: D | F7: 승률 53% 이상
A8: S | B8: 7 | C8: 로켓 라쿤 | D8: 53.7 | E8: P | F8: 승률 53% 이상
A9: S | B9: 8 | C9: 미스터 판타스틱 | D9: 53.1 | E9: R | F9: 승률 53% 이상
A10: A | B10: 9 | C10: 데빌 다이노서 | D10: 52.7 | E10: R
A11: A | B11: 10 | C11: 헐크 | D11: 52.2 | E11: R
A12: A | B12: 11 | C12: 스칼렛 위치 | D12: 52 | E12: D/R
A13: A | B13: 12 | C13: 토르 | D13: 52 | E13: R
A14: A | B14: 13 | C14: 블레이드 | D14: 52 | E14: D
A15: A | B15: 14 | C15: 앤젤라 | D15: 51.9 | E15: R
A16: A | B16: 15 | C16: 캡틴 아메리카 | D16: 51.8 | E16: D/R
A17: A | B17: 16 | C17: 헬라 | D17: 51.6 | E17: P/D
A18: A | B18: 17 | C18: 아이언맨 | D18: 51.6 | E18: P
A19: B | B19: 18 | C19: 후드 | D19: 51.3 | E19: P
A20: B | B20: 19 | C20: 데어데블 | D20: 51.3 | E20: D
A21: B | B21: 20 | C21: 아이언피스트 | D21: 51.1 | E21: R
... A51: D | B51: 50 | C51: 네이머 | D51: 47.2 | E51: P
A52: F | B52: 51 | C52: 땅상어 제프 | D52: 46.9 | E52: P | F52: 승률 47% 미만
A53: F | B53: 52 | C53: 데드풀(뱅가드) | D53: 46.3 | E53: R | F53: 승률 47% 미만
A54: F | B54: 53 | C54: 사이클롭스 | D54: 45.8 | E54: P | F54: 승률 47% 미만
A55: F | B55: 54 | C55: 피닉스 | D55: 45.6 | E55: P | F55: 승률 47% 미만
A56: F | B56: 55 | C56: 퍼니셔 | D56: 45.6 | E56: P | F56: 승률 47% 미만
A57: F | B57: 56 | C57: 스쿼럴 걸 | D57: 45.2 | E57: P | F57: 승률 47% 미만
A59: 출처: counterwatch.gg (커뮤니티 경기 통계, 전 랭크·스탠다드 모드, 시즌 10, 2026-10-15 갱신)
A60: ※ 승률은 '축소 승률'(표본이 적은 영웅이 우연히 상위에 오르지 않도록 보정한 승률) 기준입니다.
A61: ※ 티어 구간: S 53% 이상 … F 47% 미만 (사이트 설명 기준). 랭크·모드에 따라 순위가 달라질 수 있습니다.
A62: ※ 데드풀은 역할별, 헐크는 사이트 표기상 '브루스 배너'로 집계됩니다.

Sheet 카운터
A1: 영웅(상대) | B1: 티어 | C1: 1순위 카운터 | D1: 2순위 | E1: 3순위 | F1: 4순위 | G1: 5순위 | H1: 이 영웅이 강한 상대(역카운터)
A2: 갬빗 | B2: C | C2: 블랙 팬서 (+10.7, 팀 단위 압박) | D2: 스파이더맨 (+7.0, 팀 단위 압박) | E2: 베놈 (+5.2, 팀 단위 압박) | F2: 스쿼럴 걸 (+4.6, 복합 위협) | G2: 블랙 캣 (+4.2, 팀 단위 압박) | H2: 퍼니셔, 데빌 다이노서, 헬라
A3: 고르 | B3: S | C3: 페니 파커 (+12.8, 1:1 대결 우세) | D3: 데빌 다이노서 (+11.4, 복합 위협) | E3: 울트론 (+10.4, 복합 위협) | F3: 로그 (+5.9, 1:1 대결 우세) | G3: 데드풀(전략가) (+5.8, 팀 단위 압박) | H3: 블랙 캣, 스파이더맨, 맨티스
A4: 그루트 | B4: C | C4: 울버린 (+14.7, 1:1 대결 우세) | D4: 데빌 다이노서 (+10.6, 복합 위협) | E4: 주빌리 (+6.6, 팀 단위 압박) | F4: 후드 (+5.4, 복합 위협) | G4: 아이언피스트 (+5.2, 1:1 대결 우세) | H4: 미스터 판타스틱, 블랙 팬서, 데어데블
A5: 네이머 | B5: D | C5: 로켓 라쿤 (+11.4) | D5: 인비저블 우먼 (+7.3, 팀 단위 압박) | E5: 매그니토 (+7.3, 복합 위협) | F5: 클록 앤 대거 (+6.2, 팀 단위 압박) | G5: 로키 (+6.2, 팀 단위 압박) | H5: 스파이더맨, 스칼렛 위치, 아이언피스트
A6: 닥터 스트레인지 | B6: B | C6: 울버린 (+19.1, 복합 위협) | D6: 데빌 다이노서 (+13.5, 1:1 대결 우세) | E6: 씽 (+12.1, 1:1 대결 우세) | F6: 아이언피스트 (+7.7, 복합 위협) | G6: 블레이드 (+7.1, 복합 위협) | H6: 스파이더맨, 아담 워록, 블랙 위도우
A7: 데드풀(듀얼리스트) | B7: D | C7: 씽 (+5.3, 1:1 대결 우세) | D7: 베놈 (+4.8, 복합 위협) | E7: 고르 (+4.4, 복합 위협) | F7: 로그 (+4.1, 1:1 대결 우세) | G7: 매그니토 (+3.4, 복합 위협) | H7: 아이언맨, 인비저블 우먼, 맨티스
A8: 데드풀(뱅가드) | B8: F | C8: 주빌리 (+7.5, 팀 단위 압박) | D8: 클록 앤 대거 (+5.3) | E8: 화이트 폭스 (+5.1, 팀 단위 압박) | F8: 맨티스 (+4.6, 팀 단위 압박) | G8: 루나 스노우 (+3.4, 팀 단위 압박) | H8: 아이언맨, 휴먼 토치, 울트론
A9: 데드풀(전략가) | B9: D | C9: 블레이드 (+5.3, 팀 단위 압박) | D9: 문나이트 (+5.2, 팀 단위 압박) | E9: 클록 앤 대거 (+5.0) | F9: 스쿼럴 걸 (+3.6, 팀 단위 압박) | G9: 매직 (+3.6, 팀 단위 압박) | H9: 울버린, 고르, 아이언피스트
A10: 데빌 다이노서 | B10: A | C10: 스쿼럴 걸 (+14.8, 1:1 대결 우세) | D10: 피닉스 (+14.6, 1:1 대결 우세) | E10: 퍼니셔 (+14.3, 1:1 대결 우세) | F10: 문나이트 (+11.9, 1:1 대결 우세) | G10: 사이클롭스 (+11.6, 복합 위협) | H10: 앤젤라, 캡틴 아메리카, 미스터 판타스틱
A11: 데어데블 | B11: B | C11: 데빌 다이노서 (+15.3, 복합 위협) | D11: 페니 파커 (+14.6, 1:1 대결 우세) | E11: 로그 (+10.4, 1:1 대결 우세) | F11: 씽 (+9.7, 1:1 대결 우세) | G11: 베놈 (+8.9, 복합 위협) | H11: 로켓 라쿤, 인비저블 우먼, 사일록
A12: 땅상어 제프 | B12: F | C12: 블랙 팬서 (+22.3, 팀 단위 압박) | D12: 스파이더맨 (+11.7, 팀 단위 압박) | E12: 블랙 캣 (+9.5, 팀 단위 압박) | F12: 데어데블 (+9.3, 팀 단위 압박) | G12: 블레이드 (+5.8, 팀 단위 압박) | H12: 엘사 블러드스톤, 윈터 솔져, 울버린
... A57: 휴먼 토치 | B57: B | C57: 스파이더맨 (+11.8, 1:1 대결 우세) | D57: 앤젤라 (+8.2, 1:1 대결 우세) | E57: 데드풀(뱅가드) (+6.7, 복합 위협) | F57: 스타 로드 (+6.5, 1:1 대결 우세) | G57: 후드 (+6.5, 복합 위협) | H57: 스쿼럴 걸, 울버린, 문나이트
A59: 출처: counterwatch.gg (커뮤니티 경기 통계, 전 랭크·스탠다드 모드, 시즌 10, 2026-10-15 갱신)
A60: ※ 괄호 안 숫자 = 카운터 지수. 0이 비등한 상성이고, 클수록 '왼쪽 영웅을 더 확실히 잡아내는' 영웅입니다 (승률 %가 아닌 지수).
A61: ※ 지수는 매치 승률이 아니라 킬 로그(1:1 결투 승패, 한타에서 어느 쪽이 더 많이 죽었는지)로 계산됩니다. 그래서 보호막·치유처럼 '막아 주는' 카운터는 낮게 잡힐 수 있습니다.
A62: ※ 1:1 대결 우세 = 직접 맞붙어 이김 / 팀 단위 압박 = 팀 싸움에서 상대 팀 전체를 흔듦 / 복합 위협 = 두 가지가 섞임 (사이트 분류 번역)
A63: ※ 역카운터 = 사이트의 'Flip side' 항목: 이 영웅이 가장 강하게 잡아내는 상대 3명

Sheet 조합 성향(PDR)
A1: 영웅 | B1: 주 성향 | C1: P 포킹 | D1: D 다이브 | E1: R 러쉬 | F1: 성향 풀이
A2: 갬빗 | B2: P/D | C2: 0.5 | D2: 0.5 | E2: 0.5 | F2: 포킹 / 다이브 중심
A3: 고르 | B3: D | C3: 0.2 | D3: 0.9 | E3: 0.8 | F3: 다이브 중심
A4: 그루트 | B4: R | C4: 0.5 | D4: 0.2 | E4: 0.9 | F4: 러쉬 중심
A5: 네이머 | B5: P | C5: 0.8 | D5: 0.4 | E5: 0.6 | F5: 포킹 중심
A6: 닥터 스트레인지 | B6: P | C6: 0.8 | D6: 0.7 | E6: 0.3 | F6: 포킹 중심
A7: 데드풀(듀얼리스트) | B7: D | C7: 0.5 | D7: 1 | E7: 0.8 | F7: 다이브 중심
A8: 데드풀(뱅가드) | B8: R | C8: 0.4 | D8: 0.7 | E8: 1 | F8: 러쉬 중심
A9: 데드풀(전략가) | B9: R | C9: 0.6 | D9: 0.5 | E9: 0.9 | F9: 러쉬 중심
A10: 데빌 다이노서 | B10: R | C10: 0.3 | D10: 0.3 | E10: 1 | F10: 러쉬 중심
A11: 데어데블 | B11: D | C11: 0 | D11: 1 | E11: 0.9 | F11: 다이브 중심
A12: 땅상어 제프 | B12: P | C12: 0.6 | D12: 0.4 | E12: 0.5 | F12: 포킹 중심
A13: 로그 | B13: R | C13: 0.1 | D13: 0.7 | E13: 1 | F13: 러쉬 중심
... A57: 휴먼 토치 | B57: D | C57: 0.2 | D57: 0.9 | E57: 0.5 | F57: 다이브 중심
A59: 출처: counterwatch.gg 팀 빌더 (점수는 커뮤니티 조합 연구 기반, 사이트 앱에서 조정된 값 / 0~100%)
A60: P(포킹, Poke): 먼 거리에서 꾸준히 피해를 줘 상대가 들어오기 전에 깎아 냄. 시야(사선) 확보가 중요
A61: D(다이브, Dive): 높은 기동력으로 적 진영에 뛰어들어 핵심 대상(주로 힐러·딜러)을 고립시켜 빠르게 처치. 팀 합이 중요
A62: R(러쉬, Rush): 근거리에서 지속 피해와 치유로 밀어붙임. 버티는 힘과 압박으로 상대를 압도
A63: 상성 순환(가위바위보): 포킹 > 러쉬 > 다이브 > 포킹 (사이트 설명)
A64: 주 성향 = 세 점수 중 가장 높은 것 (동점이면 함께 표기, 예: D/R)

Sheet 맵
A1: 모드 구분 | B1: 원래 모드명 | C1: 번호 | D1: 맵 이름(한글) | E1: 맵 이름(원문) | F1: 지역(한글) | G1: 지역(원문) | H1: 출시일 | I1: 출시 시점 | J1: 이 맵 승률 TOP5 영웅 (커뮤니티 통계)
A2: 경쟁 | B2: Domination | C2: 1 | D2: 비르닌 티찰라 | E2: Birnin T'Challa | F2: 은하 제국 와칸다 | G2: Intergalactic Empire of Wakanda | H2: 2024-12-06 | I2: 정식 출시(시즌 0) | J2: 페니 파커 57.4%, 맨티스 56.6%, 울트론 55.2%, 스톰 53.8%, 매직 53.7%
A3: 경쟁 | B3: Domination | C3: 2 | D3: 헬스 헤븐 | E3: Hell's Heaven | F3: 하이드라 차테리스 기지 | G3: Hydra Charteris Base | H3: 2024-12-06 | I3: 정식 출시(시즌 0) | J3: 페니 파커 57.2%, 스톰 56.4%, 매직 56.2%, 맨티스 56.2%, 울트론 55.6%
A4: 경쟁 | B4: Domination | C4: 3 | D4: 왕궁 | E4: Royal Palace | F4: 이그스가르드 | G4: Yggsgard | H4: 2024-05-12 | I4: 클로즈드 알파 테스트 | J4: 맨티스 56.9%, 페니 파커 56.0%, 울트론 55.7%, 미스터 판타스틱 54.4%, 고르 54.3%
A5: 경쟁 | B5: Domination | C5: 4 | D5: 크라코아 | E5: Krakoa | F5: 헬파이어 갈라 | G5: Hellfire Gala | H5: 2025-04-11 | I5: 시즌 2.0 | J5: 페니 파커 57.5%, 맨티스 56.2%, 울트론 55.4%, 고르 55.1%, 스톰 55.0%
A6: 경쟁 | B6: Domination | C6: 5 | D6: 셀레스티얼의 잔해 | E6: Celestial Husk | F6: 클린타르 | G6: Klyntar | H6: 2025-07-11 | I6: 시즌 3.0 | J6: 페니 파커 57.6%, 맨티스 56.8%, 고르 55.8%, 울트론 55.7%, 매직 55.2%
A7: 경쟁 | B7: Domination | C7: 6 | D7: 신의 채석장 | E7: God Quarry | F7: - | G7: - | H7: 2026-09-24 | I7: 시즌 10.0 | J7: 페니 파커 57.5%, 울트론 56.6%, 고르 55.8%, 로켓 라쿤 55.0%, 매직 55.0%
A8: 호송 | B8: Convoy | C8: 7 | D8: 이그드라실 길 | E8: Yggdrasill Path | F8: 이그스가르드 | G8: Yggsgard | H8: 2024-05-12 | I8: 클로즈드 알파 테스트 | J8: 페니 파커 56.4%, 울트론 55.7%, 스톰 55.0%, 맨티스 54.9%, 매직 54.7%
A9: 호송 | B9: Convoy | C9: 8 | D9: 스파이더 아일랜드 | E9: Spider-Islands | F9: 도쿄 2099 | G9: Tokyo 2099 | H9: 2024-07-23 | I9: 클로즈드 베타 테스트 | J9: 스톰 55.4%, 울트론 55.3%, 매직 55.1%, 페니 파커 54.5%, 고르 54.3%
A10: 호송 | B10: Convoy | C10: 9 | D10: 미드타운 | E10: Midtown | F10: 영원한 밤의 제국 | G10: Empire of Eternal Night | H10: 2025-01-10 | I10: 시즌 1.0 | J10: 울트론 57.0%, 맨티스 56.6%, 매직 54.8%, 스톰 54.7%, 고르 53.9%
A11: 호송 | B11: Convoy | C11: 10 | D11: 아라코 | E11: Arakko | F11: 헬파이어 갈라 | G11: Hellfire Gala | H11: 2025-05-30 | I11: 시즌 2.5 | J11: 페니 파커 57.2%, 울트론 55.6%, 스톰 55.4%, 고르 55.1%, 매직 54.6%
A12: 호송 | B12: Convoy | C12: 11 | D12: 명상의 박물관 | E12: Museum of Contemplation | F12: - | G12: - | H12: 2026-01-29 | I12: 시즌 6.0 | J12: 페니 파커 57.5%, 스톰 56.1%, 울트론 55.4%, 고르 54.6%, 매직 54.1%
A13: 호송 | B13: Convoy | C13: 12 | D13: 테베 | E13: Thebes | F13: - | G13: - | H13: 2026-07-23 | I13: 시즌 9.0 | J13: 울트론 57.8%, 스톰 56.7%, 매직 56.1%, 페니 파커 56.0%, 맨티스 55.5%
... A19: 경쟁+호송 | B19: Convergence | C19: 18 | D19: 로어 맨해튼 | E19: Lower Manhattan | F19: - | G19: - | H19: 2026-04-02 | I19: 시즌 7.0 | J19: 페니 파커 59.7%, 울트론 56.2%, 맨티스 55.6%, 로켓 라쿤 54.4%, 스톰 54.2%
A21: 모드 설명
A22: 경쟁 | B22: Domination (도미네이션) | C22: 두 팀이 맵 가운데 거점 하나를 차지하려고 싸우는 모드. 거점을 점령한 팀의 점수가 약 1.2초마다 1%씩 올라 100%가 되면 라운드 승리. 3판 2선승제이며, 맵마다 서로 다른 거점이 있는 하위 맵 3개가 있음
A23: 호송 | B23: Convoy (콘보이) | C23: 공격팀은 움직이는 호송 차량을 맵 끝까지 옮기고, 수비팀은 이를 막는 모드. 공격팀이 차량 근처에 있을수록 빨라짐(최대 3명). 체크포인트 2개 (통과 시 +3분, +2분). 수비팀은 시작 전 40초 먼저 출발
A24: 경쟁+호송 | B24: Convergence (컨버전스) | C24: 처음에는 거점을 점령하고(3단계 체크포인트), 점령에 성공하면 호송 차량이 열려 호송 모드처럼 끝까지 옮기는 혼합 모드. 거점 점령 시 +3분, 이후 체크포인트 1개 통과 시 +2분
A26: ※ 대상: 빠른 대전·경쟁전에 나오는 일반 모드 맵 18개 (위키 기준, 시즌 10). 아케이드·이벤트·연습장 맵과 종료된 모드(리소스 럼블)의 맵은 제외했습니다.
A27: ※ 모드 구분 이름(경쟁/호송/경쟁+호송)은 요청하신 표기를 따랐습니다. 게임 안의 공식 한글 모드명·맵 이름은 확인하지 못해, 한글 맵 이름은 원문을 번역·음역한 비공식 표기입니다.
A28: ※ 맵·출시일·모드 규칙: 마블 라이벌즈 팬덤 위키 (Maps / Domination / Convoy / Convergence 문서).
A29: ※ 승률 TOP5: counterwatch.gg 맵 통계 (시즌 10, 전 랭크, 2026-10-15 갱신). 맵에서 80판 미만인 영웅은 제외된 '축소 승률'이며 공식 데이터가 아닙니다.

Sheet 스킬 상세
A1: 영웅 | B1: 역할 | C1: 폼/모드 | D1: 유형 | E1: 스킬명 | F1: 키(PC) | G1: 협공 파트너 | H1: 쿨타임 | I1: 궁극기 비용 | J1: 세부 수치 | K1: 설명 | L1: 원문 스킬명(참고)
A2: 아담 워록 | B2: 전략가(힐러) | D2: 일반 공격 | E2: 양자 마법 | F2: 좌클릭 | J2: 피해: 60; 거리별 피해 감소: 20m부터 감소 시작, 40m에서 60%; 발사 속도: 초당 2발; 탄약: 15; 치명타: 가능; 아바타 생명의 흐름 쿨타임 감소: 1s (치명타 시에만) | K2: 양자 에너지를 발사해 피해를 줍니다. 치명타는 아바타 생명의 흐름의 쿨타임을 감소시킵니다. | L2: Quantum Magic
A3: 아담 워록 | B3: 전략가(힐러) | D3: 궁극기 | E3: 업보의 부활 | F3: Q | I3: 4500 | J3: 부활 시 체력 회복량: 최대 체력의 30%; 부활 탐지 범위: 35m 구형 반경; 지속 시간: 10s; 부활 시 보너스 체력: 부활한 아군은 최대 체력의 70%에 해당하는 보너스 체력을 얻습니다.; 보너스 체력 감쇠: 보너스 체력이 2s에 걸쳐 0으로 감소 (5s 후 시작) | K3: 아군의 업보를 일깨워 부활시킵니다. 부활한 아군은 체력이 낮지만 잠시 동안 무적 상태가 됩니다. | L3: Karmic Revival
A4: 아담 워록 | B4: 전략가(힐러) | D4: 일반 스킬 | E4: 우주 성단 | F4: 우클릭 | J4: 피해: 발당 35; 최대 충전 투사체 수: 5; 발사 간격: 단일 충전 사격 시 0.3s, 다중 사격 시 발사 간 0.07s; 투사체 속도: 100m/s; 아바타 생명의 흐름 쿨타임 감소: 적중당 0.6s | K4: 양자 에너지를 뭉쳐 덩어리로 만든 뒤 적에게 빠르게 발사합니다. 적중할 때마다 아바타 생명의 흐름의 충전 시간이 감소합니다. | L4: Cosmic Cluster
A5: 아담 워록 | B5: 전략가(힐러) | D5: 일반 스킬 | E5: 영혼의 결속 | F5: Shift | H5: 40s | J5: 치유: 15/s; 연결 범위: 15m 구형 반경; 지속 시간: 6s; 대상당 최대 분담 피해: 250; 영혼의 결속 특성: • 아담 워록은 연결된 아군이 받는 피해의 일부를 분담합니다. / • 연결로 인해 아담 워록이 처치될 만큼의 피해를 받으면 연결이 끊어지고 체력이 1 HP 남습니다. / • 충분한 피해를 받거나, 아담 워록 또는 연결된 아군이 연결 범위를 벗어나거나, 일정 시간이 지나면 연결이 끊어집니다. / • 아담은 능력 지속 시간 동안 공중에 머물며 공격할 수 있습니다. | K5: 아군과 영혼의 결속을 맺어 지속 치유를 부여하고, 받는 피해를 결속된 대상들에게 분산시킵니다. | L5: Soul Bond
A6: 아담 워록 | B6: 전략가(힐러) | D6: 일반 스킬 | E6: 아바타 생명의 흐름 | F6: E | J6: 치유: 아군: 95, 자신: 35; 충전 횟수: 2; 충전 시간: 충전당 6s; 최대 지정 사거리: 20m; 튕김 범위: 20m 구형 반경 | K6: 아군을 지정해 튕기는 치유 에너지 줄기를 보내며, 시전 시 자신도 치유합니다. 선택된 아군이 없으면 자신을 대상으로 합니다. | L6: Avatar Life Stream
A7: 아담 워록 | B7: 전략가(힐러) | D7: 일반 스킬 | E7: 비상의 쇄도 | F7: F | J7: 이동 속도: 10m/s; 최대 자원: 120; 자원 소모량: 30/s; 자원 회복: 8/s (능력 종료 직후 시작) | K7: 하늘로 날아올라 비행 상태에 돌입하고 빠르게 전진합니다. | L7: Soaring Surge
A8: 아담 워록 | B8: 전략가(힐러) | D8: 패시브 | E8: 재생의 고치 | F8: 패시브(자동) | H8: 105s | J8: 이동 속도: 12m/s; 지속 시간: 12s; 부활 지연 시간: 3s | K8: 육체가 소멸하면 아담 워록은 영혼 상태로 자유롭게 이동해 원하는 위치에서 육체를 재구성할 수 있습니다. | L8: Regenerative Cocoon
A9: 아담 워록 | B9: 전략가(힐러) | D9: 협공 스킬 | E9: 우주 회오리 | F9: 패시브(자동) | G9: 스톰 | J9: 이동 속도 증가: 20%; 영혼의 결속 연결 범위: 20m 구형 반경 | K9: 기본 효과 - 영혼의 결속으로 연결된 팀원이 이동 속도 증가 효과를 얻습니다. | L9: Cosmic Cyclone
A10: 아담 워록 | B10: 전략가(힐러) | D10: 협공 스킬 | E10: 완벽한 설계 | F10: 우클릭 | G10: 울트론 | J10: 치유: 발당 18; 양자 마법 탄약: 25 | K10: 기본 효과 - 우주 성단이 아군을 치유합니다. | L10: Flawless Design
A11: 앤젤라 | B11: 뱅가드(탱커) | D11: 일반 공격 | E11: 이코르의 창 | F11: 좌클릭 | J11: 기본 피해: 45; 충전-피해 전환율: 35%; 사거리: 7m; 공격 간격: 0.96s | K11: 창을 들고 앞으로 돌진하며, 공격 충전량에 따라 증가하는 피해를 줍니다. 완전히 충전되면 이코르의 창이 더 큰 피해를 주고 적을 띄울 수 있습니다. | L11: Spear of Ichors
A12: 앤젤라 | B12: 뱅가드(탱커) | D12: 일반 공격 | E12: 이코르의 도끼 | F12: 좌클릭 | J12: 기본 피해: 첫 세 번의 일격: 30, 네 번째 일격: 50; 충전-피해 전환율: 45%; 사거리: 4m; 공격 간격: 첫 세 번의 일격: 0.4s, 네 번째 일격: 0.6s | K12: 쌍도끼로 앞을 향해 강력한 일격을 번갈아 휘두르며, 공격 충전량이 늘어날수록 피해가 증가합니다. 네 번째 일격은 빠르게 앞으로 돌진합니다. | L12: Axes of Ichors
A13: 앤젤라 | B13: 뱅가드(탱커) | D13: 궁극기 | E13: 헤븐의 응징 | F13: Q | I13: 3100 | J13: 투사체 속도: 60m/s; 창 충돌 피해: 투사체: 30, 효과 범위: 40; 효과 범위: 8m 구형 반경; 도약 피해: 100; 도약 효과 범위: 8m 구형 반경; 둔화율: 80%; 창 체력: 650; 창 특성: • 리본에 묶인 적은 이동기를 사용할 수 없습니다. / • 창 주변 일정 거리 안의 적은 둔화되며 중심으로 끌어당겨집니다. | K13: 창을 리본으로 감싸 힘껏 던집니다. 창이 꽂히면 리본이 주변 적을 묶습니다. 앤젤라는 창의 위치로 도약해 주변 적에게 피해를 주고 신성한 심판 구역을 생성할 수 있습니다. | L13: Heven's Retribution
A14: 앤젤라 | B14: 뱅가드(탱커) | D14: 일반 스킬 | E14: 방패 태세 | F14: 우클릭 | H14: 1s (해제 시) - 4s (파괴 시) | J14: 방패 체력: 350; 방패 체력 회복: 2s 후 초당 60 HP/s 회복 시작; 막은 피해-충전 전환율: 35% | K14: 이코르를 방패로 변형하며, 피해를 흡수하면 공격 충전량을 얻습니다. | L14: Shielded Stance
A15: 앤젤라 | B15: 뱅가드(탱커) | D15: 일반 스킬 | E15: 암살자의 돌격 | F15: Shift | H15: 4s | J15: 최대 자원: 100; 자원 소모량: 25/s, 적을 한 명 이상 운반 중이면 75/s; 사용 시 자원 비용: 20; 자원 회복: 12.5/s (능력 종료 2s 후 시작); 사용에 필요한 최소 자원: 30; 충돌 피해: 30; 이동 속도: 18m/s; 최대 운반 적 수: 2; 공격 충전량 획득: 25/s, 운반 중인 적 한 명당 50/s | K15: 가속 돌진 상태에 돌입해 밀쳐내기와 띄우기에 면역이 됩니다. 정면으로 부딪힌 적은 짧은 거리 동안 공중으로 끌려갑니다. | L15: Assassin's Charge
A16: 앤젤라 | B16: 뱅가드(탱커) | D16: 일반 스킬 | E16: 신성한 심판 | F16: E | H16: 12s | J16: 착지 피해: 30; 신성한 심판 구역 피해: 15/s; 신성한 심판 구역 범위: 반경 8m, 높이 2m의 원통형 효과 범위; 신성한 심판 구역 지속 시간: 6s; 이동 속도 증가: 35%; 적중당 보너스 체력 획득량: 자신: 50, 아군: 25; 최대 보너스 체력: 200 | K16: 아래로 급강하하며 쌍도끼로 전환하고, 착지 시 땅에 이코르를 주입해 신성한 심판 구역을 생성합니다. 구역 안에서는 이동 속도가 증가하며, 공격 시 자신과 주변 아군에게 보너스 체력을 부여합니다. | L16: Divine Judgement
A17: 앤젤라 | B17: 뱅가드(탱커) | D17: 일반 스킬 | E17: 날개 칼날 상승 | F17: E | J17: 상승 높이: 8m; 상승 시간: 0.35s; 상승 각도: 60° | K17: 하늘로 날아오르며 이코르의 창으로 다시 전환합니다. | L17: Wingblade Ascent
A18: 앤젤라 | B18: 뱅가드(탱커) | D18: 패시브 | E18: 세라핌의 비상 | F18: 패시브(자동) | J18: 활공 진입 시간: 0.1s; 활공 발동 조건: 1s 동안 5m/s보다 빠른 전진 속도 유지; 이동 속도: 10m/s; 공격 충전량 획득: 22.2/s | K18: 공중을 자유롭게 활공합니다. 비행을 지속하면 공격 충전량이 쌓입니다. | L18: Seraphic Soar
A19: 앤젤라 | B19: 뱅가드(탱커) | D19: 협공 스킬 | E19: 오딘이 인정하지 않은 자들 | F19: C | G19: 로키 | H19: 20s | J19: 환영 체력: 150 | K19: 기본 효과 - 전방에 환영을 투사합니다. 환영은 암살자의 돌격을 사용해 적을 찌릅니다. 정면으로 부딪힌 적은 잠시 동안 공중으로 끌려갑니다. | L19: Odin's Unacknowledged
A20: 앤젤라 | B20: 뱅가드(탱커) | D20: 협공 스킬 | E20: 애즈가디언즈 오브 갤럭시 | F20: C | G20: 스타 로드 | H20: 25s | J20: 위치 노출 범위: 50m 구형 반경; 내려찍기 효과 범위: 10m 구형 반경; 내려찍기 피해: 65; 내려찍기 비행 불가 지속 시간: 2s | K20: 기본 효과 - 사용 시 지정한 영역의 적 위치를 노출합니다. 다시 사용하면 내려찍기 공격을 하며, 내려찍기에 맞은 적은 비행 불가 상태가 됩니다. | L20: Asgardians of the Galaxy
A21: 블랙 캣 | B21: 듀얼리스트(딜러) | C21: 기본 | D21: 일반 공격 | E21: 고양이의 분노 | F21: 좌클릭 | J21: 피해: 35; 사거리: 3.5m; 적중 시 획득 행운: 50 | K21: 날카로운 발톱으로 전방을 할퀴습니다. | L21: Feline Fury
A22: 블랙 캣 | B22: 듀얼리스트(딜러) | C22: 기본 | D22: 일반 공격 | E22: 발톱 채찍 | F22: 좌클릭 | J22: 피해: 65; 거리별 피해 감소: 30°부터 감소 시작, 75°에서 30%; 범위: 반경 7.5m, 높이 2.5m의 150° 원뿔형 효과 범위; 공격 간격: 0.6s; 획득 보너스 체력: 적중당 25; 최대 보너스 체력: 50; 행운 비용: 150; 적중 시 획득 행운: 적중당 50 (최대 100) | K22: 줄이 달린 발톱을 발사해 파괴적인 호를 그리며 휘둘러 범위 내 모든 적에게 피해를 줍니다. 행운의 은총 능력을 발동해 사용합니다. | L22: Claw Whip
A23: 블랙 캣 | B23: 듀얼리스트(딜러) | C23: 기본 | D23: 궁극기 | E23: 명함 | F23: Q | I23: 3100 | J23: 덮치기 최대 대상 지정 거리: 40m; 덮치기 중 피해 감소: 50%; 지속 시간: 10s; 처치 시 지속 시간 증가: 3s; 발톱 일격 최대 대상 지정 거리: 8m; 발톱 일격 피해: 첫 타격: 30, 두 번째 타격: 70; 발톱 일격 시 획득 행운: 200; 특성: • 전장 어디에 있든 모든 적에게 명함을 붙여 블랙 캣에게 벽 너머로 위치를 노출합니다. / • 명함은 지속 시간이 끝나지 않는 한 적이 부활한 후에도 유지됩니다. / • 지속 시간을 연장하고 덮치기 시전을 초기화하려면 블랙 캣이 발톱 일격으로 적중한 적을 처치해야 합니다. | K23: 모든 적에게 명함을 남깁니다. 시야와 사거리 내의 적에게 즉시 돌진하여 발톱으로 찢어 피해를 줍니다. | L23: Calling Card
A24: 블랙 캣 | B24: 듀얼리스트(딜러) | C24: 기본 | D24: 일반 스킬 | E24: 실뜨기 | F24: Shift | H24: 8s | J24: 피해: 40; 돌진 거리: 15m; 적중 시 획득 행운: 150 | K24: 발톱을 세우고 앞으로 돌진하여 경로상의 모든 적을 베어 냅니다. | L24: Cat's Cradle
A25: 블랙 캣 | B25: 듀얼리스트(딜러) | C25: 기본 | D25: 일반 스킬 | E25: 운명의 전환 | F25: E | H25: 5s | J25: 투사체 속도: 120m/s; 사거리: 30m; 피해: 30; 획득 보너스 체력: 50 (적중 시); 적중 시 획득 행운: 300 | K25: 갈고리를 전방으로 발사해 적중한 적에게 피해를 주고 행운을 훔칩니다. | L25: Turn of Fortune
A26: 블랙 캣 | B26: 듀얼리스트(딜러) | C26: 기본 | D26: 일반 스킬 | E26: 유령 추격 | F26: E | H26: 2s | J26: 피해: 70; 돌진 지속 시간: 0.25s; 최대 돌진 거리: 20m; 행운 비용: 250; 적중 시 획득 행운: 125 | K26: 적에게 재빠르게 돌진해 발톱으로 연속 공격을 퍼부은 뒤 시작 위치로 순식간에 돌아옵니다. 이 동작 중에는 피해 감소를 얻습니다. | L26: Phantom Pursuit
A27: 블랙 캣 | B27: 듀얼리스트(딜러) | C27: 기본 | D27: 일반 스킬 | E27: 행운의 은총 | F27: 우클릭 | J27: 발톱 채찍 행운 비용: 150; 유령 추격 행운 비용: 250 | K27: 행운을 소모해 발톱 채찍 또는 유령 추격을 발동합니다. | L27: Fortune's Favor
A28: 블랙 캣 | B28: 듀얼리스트(딜러) | C28: 기본 | D28: 일반 스킬 | E28: 도둑의 우아함 | F28: 스페이스바 | K28: 이단 점프를 합니다. | L28: Thieving Grace
A29: 블랙 캣 | B29: 듀얼리스트(딜러) | C29: 기본 | D29: 패시브 | E29: 은밀한 캣워크 | F29: 패시브(자동) | K29: 점프를 누르고 있으면 수직 벽면을 타고 오릅니다. | L29: Stealthy Catwalk
A30: 블랙 캣 | B30: 듀얼리스트(딜러) | C30: 기본 | D30: 패시브 | E30: 말킨의 불운 | F30: 패시브(자동) | J30: 추가 피해 상실 확률: 25% | K30: 적중한 적에게 징크스를 부여합니다. 징크스에 걸린 적은 블랙 캣에게 치명타를 가할 때 일정 확률로 추가 피해를 잃습니다. | L30: Malkin Misfortune
A31: 블랙 캣 | B31: 듀얼리스트(딜러) | C31: 기본 | D31: 패시브 | E31: 끈적한 발바닥 | F31: 패시브(자동) | J31: 획득 행운 (고양이의 분노): 50; 획득 행운 (발톱 채찍): 50 (최대 100); 획득 행운 (고양이 동맹): 50 (최대 100); 획득 행운 (실뜨기): 150; 획득 행운 (유령 추격): 125; 획득 행운 (명함): 200; 획득 행운 (운명의 전환): 300; 최대 행운: 1200; 사망 시 행운 손실: 처치당하면 행운의 50%를 잃으며, 최소 200이 차감됩니다 | K31: 공격이 적에게 적중할 때마다 일정량의 행운을 훔칩니다. | L31: Sticky Paws
A32: 블랙 캣 | B32: 듀얼리스트(딜러) | C32: 기본 | D32: 협공 스킬 | E32: 고양이 동맹 | F32: C | G32: 블랙 팬서 | H32: 12s | J32: 받은 피해 임계치: 50; 효과 범위: 8m 구형 반경; 효과 범위 피해: 45; 이동 속도 증가: 3m/s (즉시 감소하기 시작해 3s에 걸쳐 0m/s가 됨); 획득 보너스 체력: 25 (발동 시); 적중 시 획득 행운: 50 (최대 100) | K32: 기본 효과 - 피해를 받으면 비브라늄 에너지가 축적됩니다. 일정 수치에 도달하면 블랙 캣이 강력한 폭발을 일으켜 주변 적에게 피해를 주고 밀쳐내며, 잠시 이동 속도 증가와 보너스 체력을 얻습니다. 적중한 적 하나당 행운을 50 얻으며, 최대 100까지 얻습니다. | L32: Feline Alliance
A33: 블랙 캣 | B33: 듀얼리스트(딜러) | C33: 기본 | D33: 협공 스킬 | E33: 결속의 끈 | F33: E | G33: 스파이더맨 | J33: 충전 횟수: 2; 충전 시간: 충전당 5s; 스파이더 트레이서 추가 피해: 45 | K33: 기본 효과 - 운명의 전환이 충전 횟수 2회의 스파이더 웹 갈고리로 대체됩니다. 갈고리를 적에게 적중시키면 행운을 훔치고 스파이더 트레이서를 부착합니다. 블랙 캣이 스파이더 트레이서가 부착된 적을 다른 능력으로 적중시키면 표식이 발동해 추가 피해를 줍니다. | L33: Binding Ties
A34: 블랙 캣 | B34: 듀얼리스트(딜러) | C34: 길디드 딜(특수 상점) | D34: 특수 상점 아이템 | E34: 황금빛 거래 | F34: F | K34: 랜덜 게이트를 통해 차원의 균열을 엽니다. 행운을 소모해 황금 성자와 거래하고 뉴욕 도둑 길드의 희귀 유물을 얻습니다. | L34: Gilded Deal
A35: 블랙 캣 | B35: 듀얼리스트(딜러) | C35: 길디드 딜(특수 상점) | D35: 특수 상점 아이템 | E35: 운명의 석판 | F35: F | J35: 행운 비용: 100; 발동 효과: 무작위로 행운 0/50/200/500 획득. | K35: 무작위 양의 행운을 얻습니다. | L35: Tablet of Destinies
A36: 블랙 캣 | B36: 듀얼리스트(딜러) | C36: 길디드 딜(특수 상점) | D36: 특수 상점 아이템 | E36: 하데스의 투구 | F36: F | J36: 행운 비용: 200; 지속 시간: 3s; 이동 속도 증가: 60% (지속 시간 동안 0%까지 감소) | K36: 일정 시간 동안 투명 상태가 됩니다. 이 동안 이동 궤적이 보이며, 주기적으로 전신이 드러납니다. | L36: Helm of Hades
A37: 블랙 캣 | B37: 듀얼리스트(딜러) | C37: 길디드 딜(특수 상점) | D37: 특수 상점 아이템 | E37: 팔틴 화염 구체 | F37: F | J37: 행운 비용: 200; 화염 구체 체력: 50; 최대 수량: 1; 최대 위치 노출 거리: 20m | K37: 신비한 팔틴 화염 구체를 소환해 주변의 모든 적의 위치를 노출하고 표식을 남깁니다. | L37: Faltine Flame Orb
A38: 블랙 캣 | B38: 듀얼리스트(딜러) | C38: 길디드 딜(특수 상점) | D38: 특수 상점 아이템 | E38: 체르노보그의 수정 | F38: F | J38: 행운 비용: 300; 발동 효과: 적용 중인 모든 제어 효과를 즉시 해제. | K38: 자신을 정화하여 적용 중인 모든 제어 효과를 즉시 제거합니다. | L38: Chernobog's Crystal
A39: 블랙 캣 | B39: 듀얼리스트(딜러) | C39: 길디드 딜(특수 상점) | D39: 특수 상점 아이템 | E39: 조나의 고리 | F39: F | J39: 행운 비용: 300; 사용 간 쿨타임: 1s; 지속 시간: 10s | K39: 표면에 포털을 열어 반대편으로 즉시 이동할 수 있게 합니다. | L39: Ring of Zona
A40: 블랙 캣 | B40: 듀얼리스트(딜러) | C40: 길디드 딜(특수 상점) | D40: 특수 상점 아이템 | E40: 멘토 피시 | F40: F | J40: 행운 비용: 300; 투사체 속도: 30m/s; 효과 범위: 반경 5m, 높이 40m의 원통형 효과 범위; 둔화율: 35% | K40: 최면 영역을 생성합니다. 영역 안의 모든 적에게 둔화를 부여하고, 이동기를 봉쇄하며, 비행 불가 상태로 만듭니다. | L40: Mento-Fish
...

Sheet 협공 스킬
A1: 영웅 | B1: 협공 스킬명 | C1: 파트너 | D1: 키(PC) | E1: 쿨타임 | F1: 세부 수치 | G1: 효과
A2: 아담 워록 | B2: 우주 회오리 | C2: 스톰 | D2: 패시브(자동) | F2: 이동 속도 증가: 20%; 영혼의 결속 연결 범위: 20m 구형 반경 | G2: 기본 효과 - 영혼의 결속으로 연결된 팀원이 이동 속도 증가 효과를 얻습니다.
A3: 아담 워록 | B3: 완벽한 설계 | C3: 울트론 | D3: 우클릭 | F3: 치유: 발당 18; 양자 마법 탄약: 25 | G3: 기본 효과 - 우주 성단이 아군을 치유합니다.
A4: 앤젤라 | B4: 오딘이 인정하지 않은 자들 | C4: 로키 | D4: C | E4: 20s | F4: 환영 체력: 150 | G4: 기본 효과 - 전방에 환영을 투사합니다. 환영은 암살자의 돌격을 사용해 적을 찌릅니다. 정면으로 부딪힌 적은 잠시 동안 공중으로 끌려갑니다.
A5: 앤젤라 | B5: 애즈가디언즈 오브 갤럭시 | C5: 스타 로드 | D5: C | E5: 25s | F5: 위치 노출 범위: 50m 구형 반경; 내려찍기 효과 범위: 10m 구형 반경; 내려찍기 피해: 65; 내려찍기 비행 불가 지속 시간: 2s | G5: 기본 효과 - 사용 시 지정한 영역의 적 위치를 노출합니다. 다시 사용하면 내려찍기 공격을 하며, 내려찍기에 맞은 적은 비행 불가 상태가 됩니다.
A6: 블랙 캣 | B6: 고양이 동맹 | C6: 블랙 팬서 | D6: C | E6: 12s | F6: 받은 피해 임계치: 50; 효과 범위: 8m 구형 반경; 효과 범위 피해: 45; 이동 속도 증가: 3m/s (즉시 감소하기 시작해 3s에 걸쳐 0m/s가 됨); 획득 보너스 체력: 25 (발동 시); 적중 시 획득 행운: 50 (최대 100) | G6: 기본 효과 - 피해를 받으면 비브라늄 에너지가 축적됩니다. 일정 수치에 도달하면 블랙 캣이 강력한 폭발을 일으켜 주변 적에게 피해를 주고 밀쳐내며, 잠시 이동 속도 증가와 보너스 체력을 얻습니다. 적중한 적 하나당 행운을 50 얻으며, 최대 100까지 얻습니다.
A7: 블랙 캣 | B7: 결속의 끈 | C7: 스파이더맨 | D7: E | F7: 충전 횟수: 2; 충전 시간: 충전당 5s; 스파이더 트레이서 추가 피해: 45 | G7: 기본 효과 - 운명의 전환이 충전 횟수 2회의 스파이더 웹 갈고리로 대체됩니다. 갈고리를 적에게 적중시키면 행운을 훔치고 스파이더 트레이서를 부착합니다. 블랙 캣이 스파이더 트레이서가 부착된 적을 다른 능력으로 적중시키면 표식이 발동해 추가 피해를 줍니다.
A8: 블랙 팬서 | B8: 다미사-야오 | C8: 스톰 | D8: C | E8: 15s | F8: 효과 범위: 반경 8m 구형; 피해: 30; 둔화율: 35%; 둔화 지속 시간: 2s | G8: 기본 효과 - 갑옷 안의 원소의 힘을 발동해 주변 적에게 피해와 둔화를 부여하고 비브라늄 표식을 부여합니다.
A9: 블랙 팬서 | B9: 차원 지름길 | C9: 매직 | D9: C | E9: 35s | F9: 획득 보너스 체력: 50; 붕괴 효과 범위: 반경 8m 구형; 붕괴 피해: 40 | G9: 기본 효과 - 림보 디딤 원반을 발동해 몇 초 전의 위치로 즉시 되돌아가며 보너스 체력을 얻습니다. 순간이동이 끝나면 원반이 붕괴하며 폭발해 주변 적에게 피해를 입히고 비브라늄 표식을 부여합니다.
A10: 블랙 위도우 | B10: 연합 요원 | C10: 호크아이 | D10: 패시브(자동) | F10: 적중 시 집중 획득: 1; 치명타 시 집중 획득: 2; 집중 사격 피해: 발당 55 | G10: 기본 효과 - 레드 룸 소총으로 적중시키면 집중이 쌓입니다. 세 번 중첩되면 집중 상태에 돌입해 다음 탄환이 사냥꾼의 시야 효과를 얻어 피해 증가 및 관통 효과를 갖습니다.
A11: 블랙 위도우 | B11: 불타는 탄환 | C11: 피닉스 | D11: 패시브(자동) | E11: 10s | F11: 레드 룸 소총 공격 속도 증가: 15%; 피해: 70; 폭발 범위: 5m 구형 반경; 둔화율: 40%; 둔화 지속 시간: 3s | G11: 기본 효과 - 사용 시 레드 룸 소총의 발사 속도가 증가합니다. 또한 플라스마 캐논 투사체가 충전이 필요 없는 즉발(히트스캔) 레이저로 바뀝니다.
A12: 블레이드 | B12: 콘슈의 칼날 | C12: 문나이트 | D12: C | E12: 12s | F12: 돌진 지속 시간: 0.15s; 돌진 속도: 60m/s; 달 칼날 피해: 40; 달 칼날 투사체 속도: 150m/s; 발사되는 달 칼날 수: 4; 달 칼날 피해 감소: 튕길 때마다 35% | G12: 기본 효과 - 짧게 돌진하며 선조의 검으로 전방을 강하게 내려벱니다. 돌진이 끝나면 재빠르게 네 번 베어 매 타격마다 어둠달 칼날을 전방으로 날립니다. 어둠달 칼날이 적에게 적중하면 근처 대상에게 튕겨 나갑니다.
A13: 블레이드 | B13: 전투를 위한 피 | C13: 캡틴 아메리카 | D13: 패시브(자동) | F13: 받은 피해로 얻는 중첩: 피해를 40 받을 때마다 중첩 1 획득; 최대 혈통 각성 중첩: 12 | G13: 기본 효과 - 블레이드가 일정량의 피해를 받을 때마다 혈통 각성 중첩을 하나 쌓습니다.
A14: 캡틴 아메리카 | B14: 전압 결합 | C14: 토르 | D14: C | E14: 15s | F14: 지속 시간: 10s; 번개 방패 던지기 피해: 45 | G14: 기본 효과 - 센티넬 일격이 번개 방패 투사체로 바뀝니다. 두 번 적중시키면 캡틴 아메리카가 관통하는 번개 방패를 네 번 던집니다.
A15: 캡틴 아메리카 | B15: 별의 정렬 | C15: 윈터 솔져 | D15: C | E15: 12s | F15: 획득 보너스 체력: 150 (자신 및 아군); 피해 흡수 지속 시간: 2s | G15: 기본 효과 - 캡틴 아메리카가 아군에게 곧바로 도약해 자신과 아군에게 보너스 체력을 부여하고, 아군이 받는 피해의 일부를 자신에게 돌립니다.
A16: 클록 앤 대거 | B16: 망각의 장막 | C16: 후드 | D16: E | F16: 장막 유지 시간: 4s; 장막 크기: 너비: 6m, 높이: 4.5m; 빛의 장막 피해 감소량: 20%; 어둠의 장막 치유 감소량: 20% | G16: 기본 효과 - 라이트포스 장막과 공포의 망토가 지옥불 에너지로 뒤틀려 기존 효과를 유지한 채 황혼의 장막과 공허의 장막으로 바뀝니다. 장막은 일정 거리를 이동한 뒤 그 자리에 멈춥니다. 황혼의 장막을 통과하는 적의 피해는 약화되며, 공허의 장막을 통과하는 적의 치유에는 치유 감소가 적용됩니다.
A17: 클록 앤 대거 | B17: 얼어붙은 안식처 | C17: 루나 스노우 | D17: C | E17: 20s | F17: 지속 시간: 2s; 치유: 50/s; 치유 오라 범위: 구형 반경 8m | G17: 기본 효과 - 냉기 에너지를 바깥으로 방출해 자신을 단단한 얼음 덩어리에 가둡니다. 강력한 보호를 받지만 그 자리에 빙결됩니다. 빙결 중에도 치유를 받을 수 있으며, 주변 아군에게 약한 치유 오라를 방출합니다.
A18: 사이클롭스 | B18: 날씬하고 빨간 | C18: 피닉스 | D18: E | E18: 2s | F18: 충전 횟수: 2; 충전 시간: 충전당 15s; 화상 피해: 0.5s마다 7 피해; 화상 지속 시간: 3s; 폭발 피해: 남은 화상 피해의 50% | G18: 기본 효과 - 도탄의 힘으로 적을 적중하면 피닉스 포스를 소환해 적에게 불을 붙여 일정 시간 동안 지속 화상 피해를 줍니다. 불붙은 대상을 광학 블래스트 또는 충격 광선으로 적중하면 남은 화상 피해의 일정 비율을 한 번에 즉시 터뜨립니다.
A19: 사이클롭스 | B19: 키네틱 혈족 | C19: 갬빗 | D19: C | E19: 15s | F19: 지속 시간: 8s; 이동 속도 증가: 40%; 강화 점프 속도: 5m/s | G19: 기본 효과 - 저장된 운동 에너지를 방출해 일정 시간 동안 강화 상태에 돌입합니다. 강화 상태 동안 사이클롭스의 이동 속도와 점프 높이가 크게 증가합니다.
A20: 데어데블 | B20: 종합 방어 | C20: 아이언피스트 | D20: 우클릭 | G20: 기본 효과 - 이의 있음!이 강화됩니다. 회전하는 곤봉이 이제 범위 내 모든 적에게 피해를 주며 모든 방향의 투사체를 반사합니다. 공격을 반사하는 데 성공하면 분노를 회복합니다.
A21: 데어데블 | B21: 악마 같은 거래 | C21: 블랙 위도우 | D21: C | E21: 12s | F21: 피해: 55; 공격 범위: 반경 8.5m, 높이 5m, 120° 원뿔형 효과 범위; 둔화율: 40%; 둔화 지속 시간: 1.5s | G21: 기본 효과 - 악마의 사슬을 X자로 휘둘러 전방의 적에게 피해를 주고 둔화를 부여합니다.
A22: 데드풀 | B22: "헬-예, 허니" [뱅가드] | C22: 헬라 | D22: 패시브(자동) | F22: 끝내주는 카타나 폭발 피해: 5 + 최대 체력의 1.5% | G22: 기본 효과 - 헬로부터 업그레이드를 받아 데저트 이글 또는 카타나를 한 번 더 업그레이드할 수 있습니다. 헬-예 데저트 이글: 듀얼리스트와 뱅가드는 관통 효과를 얻고, 생각 말풍선이 유도 기능이 있는 죽음의 말풍선으로 변합니다. 전략가의 죽음의 말풍선은 아군에게도 유도되어 폭발하며 치유를 제공합니다. 헬-예 카타나: 공격할 때마다 적에게 언데드 에너지를 주입합니다. 카타나로 적을 세 번 적중시키면 에너지가 폭발해 대상의 최대 체력에 비례한 비율 고정 피해를 입힙니다.
A23: 데드풀 | B23: 검보 치미창가 [뱅가드] | C23: 갬빗 | D23: C | E23: 15s | F23: 착지 피해: 60; 착지 효과 범위: 반경 5m 구형 | G23: 기본 효과 - 운동 에너지를 발동해 데드풀이 앞으로 도약합니다. 착지하면 운동 에너지가 충전된 치미창가를 고리 모양으로 흩뿌려 적에게 피해를 입힙니다.
A24: 데드풀 | B24: "헬-예, 허니" [듀얼리스트] | C24: 헬라 | D24: 패시브(자동) | F24: 끝내주는 카타나 폭발 피해: 5 + 최대 체력의 2% | G24: 기본 효과 - 헬로부터 업그레이드를 받아 데저트 이글 또는 카타나를 한 번 더 업그레이드할 수 있습니다. 헬-예 데저트 이글: 듀얼리스트와 뱅가드는 관통 효과를 얻고, 생각 말풍선이 유도 기능이 있는 죽음의 말풍선으로 변합니다. 전략가의 죽음의 말풍선은 아군에게도 유도되어 폭발하며 치유를 제공합니다. 헬-예 카타나: 공격할 때마다 적에게 언데드 에너지를 주입합니다. 카타나로 적을 세 번 적중시키면 에너지가 폭발해 대상의 최대 체력에 비례한 비율 고정 피해를 입힙니다.
A25: 데드풀 | B25: 검보 치미창가 [듀얼리스트] | C25: 갬빗 | D25: C | E25: 15s | F25: 착지 피해: 90; 착지 효과 범위: 반경 5m 구형 | G25: 기본 효과 - 운동 에너지를 발동해 데드풀이 앞으로 도약합니다. 착지하면 운동 에너지가 충전된 치미창가를 고리 모양으로 흩뿌려 적에게 피해를 입힙니다.
A26: 데드풀 | B26: "헬-예, 허니" [전략가] | C26: 헬라 | D26: 패시브(자동) | F26: 끝내주는 카타나 폭발 피해: 5 + 최대 체력의 0.5%; 폭발 시 자가 치유: 5 | G26: 기본 효과 - 헬로부터 업그레이드를 받아 데저트 이글 또는 카타나를 한 번 더 업그레이드할 수 있습니다. 헬-예 데저트 이글: 듀얼리스트와 뱅가드는 관통 효과를 얻고, 생각 말풍선이 유도 기능이 있는 죽음의 말풍선으로 변합니다. 전략가의 죽음의 말풍선은 아군에게도 유도되어 폭발하며 치유를 제공합니다. 헬-예 카타나: 공격할 때마다 적에게 언데드 에너지를 주입합니다. 카타나로 적을 세 번 적중시키면 에너지가 폭발해 대상의 최대 체력에 비례한 비율 고정 피해를 입힙니다.
A27: 데드풀 | B27: 검보 치미창가 [전략가] | C27: 갬빗 | D27: C | E27: 15s | F27: 착지 피해: 35; 착지 치유: 65; 착지 효과 범위: 반경 5m 구형 | G27: 기본 효과 - 운동 에너지를 발동해 데드풀이 앞으로 도약합니다. 착지하면 운동 에너지가 충전된 치미창가를 고리 모양으로 흩뿌려 적에게 피해를 입히고 아군을 추가로 치유합니다.
A28: 데빌 다이노서 | B28: 원시의 응징 | C28: 퍼니셔 | D28: C | E28: 12s | F28: 지속 시간: 8s; 피해: 투사체: 5, 효과 범위: 20; 효과 범위: 3m 구형 반경; 발사 간격: 0.25s; 투사체 속도: 150m/s | G28: 기본 효과 - 새로운 능력이 추가됩니다. 발동 시 원시의 물어뜯기가 대체됩니다. 데빌 다이노서가 전방으로 발사할 수 있는 자기 대포 두 문을 얻으며, 포탄은 적이나 지형에 닿으면 폭발하여 출혈을 부여합니다.
A29: 데빌 다이노서 | B29: 바다와 육지 | C29: 땅상어 제프 | D29: 우클릭 | F29: 광선 사거리: 20m; 최대 광선 지속 시간: 5s; 치유: 60/s | G29: 기본 효과 - 충격 빔이 전방 물줄기 분사로 대체됩니다. 이 물줄기는 적에게 피해를 주고 아군을 치유합니다.
A30: 닥터 스트레인지 | B30: 감마 소용돌이 | C30: 헐크(브루스 배너) | D30: E | E30: 6s | F30: 피해: 암흑 마법 포인트당 1.3 피해; 효과 범위: 10m 구형 반경 | G30: 기본 효과 - 광기의 소용돌이를 감마 소용돌이로 강화합니다. 에너지 충전 속도가 크게 증가하고 치유 불가 저주가 제거됩니다.
A31: 닥터 스트레인지 | B31: 사이오닉 소용돌이 | C31: 인비저블 우먼 | D31: E | E31: 6s | F31: 피해: 암흑 마법 포인트당 1.3 피해; 효과 범위: 8m 구형 반경; 세라핌의 방패 체력: 1000 | G31: 기본 효과 - 광기의 소용돌이를 사이오닉 소용돌이로 강화합니다. 범위에 휘말린 적은 자신 쪽으로 끌려옵니다. 세라핌의 방패의 보호막 수치도 증가합니다.
A32: 엘사 블러드스톤 | B32: 선사 시대 덫 | C32: 데빌 다이노서 | D32: F | E32: 15s | F32: 덫 발동 범위: 구형 반경 5m; 덫 체력: 50; 속박 지속 시간: 1.2s; 발동 피해: 30; 가스 범위: 구형 반경 3m; 가스 피해: 35/s; 가스 지속 시간: 2s; 더블 배럴 블래스터 피해: 펠릿당 5 | G32: 기본 효과 - 연기 덫을 설치하면 디아블로가 주변을 감시합니다. 적이 접근하면 디아블로가 적을 속박하고 피해를 줍니다. 또한 치명적인 가스를 방출해 지속적인 범위 피해를 줍니다.
A33: 엘사 블러드스톤 | B33: 수다쟁이 용병들 | C33: 데드풀 | D33: 우클릭 | E33: 8s | F33: 피해: 첫 발: 60, 파편: 40; 지속 피해: 20/s; 둔화율: 25%; 효과 지속 시간: 2s; 피해량-치유 전환율: 30% | G33: 기본 효과 - 살아있는 탄환이 특수탄으로 바뀌어 데드풀의 수다로 대상을 도발하고, 주변 적에게 둔화를 걸며 지속 피해를 줍니다. 일정 시간이 지나면 탄환이 자동으로 회수되어, 가한 피해에 비례해 엘사를 치유하고 물려받은 본능 패시브의 최대치에 게이지 칸 하나를 추가합니다.
A34: 엠마 프로스트 | B34: 영혼 파괴자 | C34: 맨티스 | D34: E | F34: 피해-보너스 체력 전환율: 150% | G34: 기본 효과 - 적의 정신체에 가한 피해가 그대로 보너스 체력으로 전환됩니다.
A35: 엠마 프로스트 | B35: 아이스드 아웃 다이아몬드 | C35: 루나 스노우 | D35: C | E35: 12s | F35: 방벽 체력: 350; 방벽 크기: 반경 8m, 높이 3m, 60° 원뿔형 효과 범위; 피해: 50; 둔화율: 25%; 둔화 지속 시간: 2s | G35: 기본 효과 - 전방으로 얼음 에너지를 방출해 적에게 피해를 주고 둔화시킵니다. 다이아몬드 형태에서는 냉기를 응축해 적의 공격과 이동을 막는 절대 영도 다이아몬드 방벽을 생성합니다.
A36: 갬빗 | B36: 유리한 확률 | C36: 매그니토 | D36: C | E36: 15s | F36: 지속 시간: 5s; 효과 범위: 5m 구형 반경; 피해: 50/s; 치유: 55/s | G36: 기본 효과 - 자성을 띤 카드 두 장을 전방으로 던집니다. 지형이나 캐릭터에 적중하면 두 카드가 자력으로 밀어내며 펼쳐져 일정 시간 동안 제자리에서 회전합니다. 닿은 아군은 치유하고, 적에게는 피해를 주며 띄웁니다.
A37: 갬빗 | B37: 반짝이는 지팡이 | C37: 주빌리 | D37: C | E37: 12s | F37: 지속 시간: 2s; 피해: 45/s; 피해 범위: 5m 구형 반경; 치유: 70/s; 치유 범위: 8m 구형 반경 | G37: 기본 효과 - 불꽃 에너지로 강화된 봉을 회전시킵니다. 사방으로 퍼지는 불꽃이 주변 아군을 치유합니다. 동시에 봉이 근거리의 적에게 피해를 주며, 빠른 회전으로 대부분의 투사체 피해를 막아냅니다.
A38: 고르 | B38: 라그나로크 | C38: 헬라 | D38: C | E38: 20s | F38: 피해: 45; 공격 범위: 5m 구형 반경; 비행 불가 지속 시간: 1s | G38: 기본 효과 - 올 블랙을 낫으로 변형해 휩쓸기 공격을 가하는 새 스킬을 얻어, 근처 적에게 피해를 주고 잠시 비행 불가 상태로 만듭니다. 무기는 짧은 시간 동안 낫 형태를 유지합니다.
A39: 고르 | B39: 군체 의식 | C39: 베놈 | D39: C | E39: 15s | F39: 피해: 발사: 40, 회수: 20; 사거리: 25m | G39: 기본 효과 - 전방으로 심비오트 발톱을 발사하는 새 스킬을 얻어, 경로상의 적에게 관통 피해를 줍니다. 최대 거리에 도달하면 되돌아오며, 붙잡힌 적을 고르 쪽으로 띄워 끌어옵니다.
A40: 그루트 | B40: 야생의 벽 | C40: 맨티스 | D40: C | E40: 10s | F40: 보너스 체력 획득량: 10 (1s마다; 버프 활성 중에만); 치유: 20/s; 강화 범위: 15m 구형 반경; 장벽 체력: 200; 버프 지속 시간: 6s (각성 반경을 벗어나도 유지) | G40: 기본 효과 - 범위 내 아군에게 지속 치유와 보너스 체력을 제공하는 야생의 벽을 소환합니다.
...

Sheet 출처
A1: 구분 | B1: 주소 | C1: 사용한 내용
A2: 공식 | B2: https://www.marvelrivals.com/kr/index.html | C2: 공식 홈페이지 (사용자가 알려준 주소)
A3: 공식 | B3: https://www.marvelrivals.com/kr/heroes/index.html | C3: 한글 영웅명 33명 (공식 페이지에는 체력·스킬 수치 없음)
A4: 위키 | B4: https://marvelrivals.fandom.com/wiki/Heroes | C4: 영웅 수(54명), 역할 분포, 이동 속도 일반 설명
A5: 위키 | B5: https://marvelrivals.fandom.com/wiki/Category:Vanguards | C5: 뱅가드 목록
A6: 위키 | B6: https://marvelrivals.fandom.com/wiki/Category:Duelists | C6: 듀얼리스트 목록
A7: 위키 | B7: https://marvelrivals.fandom.com/wiki/Category:Strategists | C7: 전략가 목록
A8: 위키(영웅) | B8: https://marvelrivals.fandom.com/wiki/Adam_Warlock | C8: 아담 워록: 역할·체력·난이도
A9: 위키(스킬) | B9: https://marvelrivals.fandom.com/wiki/Template:Abilities/Adam_Warlock | C9: 아담 워록: 스킬·쿨타임·궁극기 비용·세부 수치
A10: 위키(영웅) | B10: https://marvelrivals.fandom.com/wiki/Angela | C10: 앤젤라: 역할·체력·난이도
A11: 위키(스킬) | B11: https://marvelrivals.fandom.com/wiki/Template:Abilities/Angela | C11: 앤젤라: 스킬·쿨타임·궁극기 비용·세부 수치
A12: 위키(영웅) | B12: https://marvelrivals.fandom.com/wiki/Black_Cat | C12: 블랙 캣: 역할·체력·난이도
... A124: 커뮤니티 통계 | B124: https://www.counterwatch.gg/stats/marvel-rivals/maps | C124: 맵별 승률 상위 영웅 (커뮤니티 통계)
